Workbook

Sheet Statement
A1: gvóvi wm‡g· †ccvi wjt
A2: Kz`ve, c~evBj, MvRxcyi (BDwbU-2) Qbcvov, AvovBnvRvi, bvivqbMÄ (&BDwbU-3)
A3: RvZxq wkÿvµg I cvV¨cy¯ÍK †evW© Gi 2027 wkÿve‡l©i cvV¨cy¯ÍK (gy`ªY, evavuB, mieivn) Kv‡Ri weeiY
M4: ZvwiLt 02.08.2026
A5: BDwbU-2 (Kz`ve, c~evBj, MvRxcyi)
A6: µwgK | B6: ‡kÖbx | C6: jU bs | D6: jU msL¨v | E6: ‡cøU Pvwn`v | F6: ‡gvU eB | G6: ‡gvU B‡¤úªkb | H6: wig | K6: ‡ccvi Pvwn`v | O6: gšÍe¨
H7: 4 Kvjvi | I7: 1 Kvjvi | J7: ‡gvU wig | K7: 70-29.5 | L7: 80-29.5 wRGmGg | M7: 80-33.5 | N7: ‡gvU ‡cøU
A8: 1 | B8: wcÖ-cÖvBgvix | C8: 123 | D8: Avgvi eB | E8: ='MSPL-2 (Class)'!M7 -> 192 | F8: ='MSPL-2 (Class)'!K7 -> 66398 | G8: ='MSPL-2 (Class)'!R7 -> 713778.5 | H8: ='MSPL-2 (Class)'!AD7 -> 1427.557 | J8: ='MSPL-2 (Class)'!AD7 -> 1427.557 | M8: =J8/50 -> 28.55114
D9: LvZv | E9: ='MSPL-2 (Class)'!M8 -> 18 | F9: ='MSPL-2 (Class)'!K8 -> 66398 | G9: ='MSPL-2 (Class)'!R8 -> 564383 | I9: ='MSPL-2 (Class)'!AD8 -> 1128.766 | J9: ='MSPL-2 (Class)'!AD8 -> 1128.766 | L9: =J9/65 -> 17.365631
A10: 2 | B10: cÖvBgvix | C10: 329338347375401 | D10: 5wU | E10: ='MSPL-2 (Class)'!M70 -> 4856 | F10: ='MSPL-2 (Class)'!K70 -> 4031896 | G10: ='MSPL-2 (Class)'!R70 -> 31161631 | H10: ='MSPL-2 (Class)'!AD70 -> 62323.261 | J10: ='MSPL-2 (Class)'!AD70 -> 62323.261 | L10: =J10/65 -> 958.81941
A11: 3 | B11: 7g | C11: 706708757759762 | D11: 5wU | E11: ='MSPL-2 (Class)'!M102 -> 792 | F11: ='MSPL-2 (Class)'!K102 -> 2188607 | G11: ='MSPL-2 (Class)'!R102 -> 9928182.2 | H11: ='MSPL-2 (Class)'!AD89 -> 1873.761 | I11: ='MSPL-2 (Class)'!AD80+'MSPL-2 (Class)'!AD81+'MSPL-2 (Class)'!AD82+'MSPL-2 (Class)'!AD83+'MSPL-2 (Class)'!AD84+'MSPL-2 (Class)'!AD85+'MSPL-2 (Class)'!AD86+'MSPL-2 (Class)'!AD87+'MSPL-2 (Class)'!AD88+'MSPL-2 (Class)'!AD90+'MSPL-2 (Class)'!AD91+'MSPL-2 (Class)'!AD92+'MSPL-2 (Class)'!AD93+'MSPL-2 (Class)'!AD94+'MSPL-2 (Class)'!AD95+'MSPL-2 (Class)'!AD96+'MSPL-2 (Class)'!AD97+'MSPL-2 (Class)'!AD98+'MSPL-2 (Class)'!AD99+'MSPL-2 (Class)'!AD100+'MSPL-2 (Class)'!AD101 -> 32960.487 | J11: ='MSPL-2 (Class)'!AD102 -> 34834.248 | K11: =J11/75 -> 464.45663
A12: 4 | B12: beg-mvwnZ¨ | C12: 926938953963 | D12: 4wU | E12: ='MSPL-2 (Class)'!M131 -> 752 | F12: ='MSPL-2 (Class)'!K131 -> 1246343 | G12: ='MSPL-2 (Class)'!R131 -> 9731784.8 | I12: ='MSPL-2 (Class)'!AD131 -> 37139.76 | J12: ='MSPL-2 (Class)'!AD131 -> 37139.76 | K12: =J12/75 -> 495.19679
A13: 5 | B13: beg-Kvjvi | C13: 1122 | D13: 1wU | E13: ='MSPL-2 (Class)'!M159 -> 1400 | F13: ='MSPL-2 (Class)'!K159 -> 295274 | G13: ='MSPL-2 (Class)'!R159 -> 4708344.5 | H13: ='MSPL-2 (Class)'!AD159 -> 9416.689 | J13: ='MSPL-2 (Class)'!AD159 -> 9416.689 | K13: =J13/75 -> 125.55585
A14: 6 | B14: beg-`vwLj | C14: 1055 | D14: 1wU | E14: ='MSPL-2 (Class)'!M206 -> 578 | F14: ='MSPL-2 (Class)'!K206 -> 287460 | G14: ='MSPL-2 (Class)'!R206 -> 2363805 | I14: ='MSPL-2 (Class)'!AD206 -> 8915.73 | J14: ='MSPL-2 (Class)'!AD206 -> 8915.73 | K14: =J14/75 -> 118.8764
A15: me©‡gvU | D15: 17 wU | E15: =SUM(E8:E14) -> 8588 | F15: =SUM(F8:F14) -> 8182376 | G15: =SUM(G8:G14) -> 59171909 | H15: =SUM(H8:H14) -> 75041.268 | I15: =SUM(I8:I14) -> 80144.742 | J15: =SUM(J8:J14) -> 155186.01 | K15: =SUM(K8:K14) -> 1204.0857 | L15: =SUM(L8:L14) -> 976.18504 | ... O15: =SUM(O8:O14) -> 0
A17: BDwbU-3 (Qbcvov, AvovBnvRvi, bvivqbMÄ)
A18: µwgK | B18: ‡kÖbx | C18: jU bs | D18: jU msL¨v | F18: ‡gvU eB | G18: ‡gvU B‡¤úªkb | J18: ‡gvU wig | K18: ‡ccvi Pvwn`v | O18: gšÍe¨
K19: 70-29.5 | L19: 80-29.5 wRGmGg | M19: 80-33.5 | N19: ‡gvU ‡cøU
A20: 1 | B20: cÖvBgvix | C20: 376379 | D20: 2wU | F20: ='MSPL-3(Class)'!L34 -> 1396833 | G20: ='MSPL-3(Class)'!N34 -> 10754081 | J20: ='MSPL-3(Class)'!Z34 -> 21508.162 | L20: =J20/65 -> 330.8948
A21: 2 | B21: Be‡Z`vqx | C21: 2022 | D21: 1wU | F21: ='MSPL-3(Class)'!L64 -> 862368 | G21: ='MSPL-3(Class)'!N64 -> 4873221.8 | J21: ='MSPL-3(Class)'!Z64 -> 9746.4435 | L21: =J21/65 -> 149.94528
A22: 3 | B22: 6ô gva¨wgK | C22: 646 | D22: 1wU | F22: ='MSPL-3(Class)'!L102 -> 407322 | G22: ='MSPL-3(Class)'!N102 -> 1567424.8 | J22: ='MSPL-3(Class)'!Z102 -> 5418.2295 | K22: =J22/75 -> 72.24306
A23: 4 | B23: 6ô `vwLj | C23: 667 | D23: 1wU | F23: ='MSPL-3(Class)'!L133 -> 693254 | G23: ='MSPL-3(Class)'!N133 -> 2768978.5 | J23: ='MSPL-3(Class)'!Z133 -> 10012.573 | K23: =J23/75 -> 133.50097
A24: 5 | B24: 8g gva¨wgK | C24: 834-843-854-865-872-877 | D24: 6wU | F24: ='MSPL-3(Class)'!L177 -> 2933769 | G24: ='MSPL-3(Class)'!N177 -> 14405581 | J24: ='MSPL-3(Class)'!Z177 -> 53170.316 | K24: =J24/75 -> 708.93755
A25: me©‡gvU | D25: 11wU | F25: =SUM(F20:F24) -> 6293546 | G25: =SUM(G20:G24) -> 34369287 | J25: =SUM(J20:J24) -> 99855.724 | K25: =SUM(K20:K24) -> 914.68158 | L25: =SUM(L20:L24) -> 480.84008 | M25: =SUM(M20:M24) -> 0 | N25: =SUM(N20:N24) -> 0 | O25: =SUM(O20:O24) -> 0
A27: BDwbU-2 Ges BDwbU-3 me©‡gvU | D27: 28wU | F27: =F25+F15 -> 14475922 | G27: =G25+G15 -> 93541196 | J27: =J25+J15 -> 255041.73 | K27: =K25+K15 -> 2118.7673 | L27: =L25+L15 -> 1457.0251 | M27: =M25+M15 -> 28.55114 | N27: =N25+N15 -> 0 | O27: =O25+O15 -> 0

Sheet Report-2
A1: gvóvi wm‡g· †ccvi wjt
A2: Kz`ve, c~evBj, MvRxcyi (BDwbU-2) Qbcvov, AvovBnvRvi, bvivqbMÄ (&BDwbU-3)
A3: RvZxq wkÿvµg I cvV¨cy¯ÍK †evW© Gi 2027 wkÿve‡l©i cvV¨cy¯ÍK (gy`ªY, evavuB, mieivn) Kv‡Ri weeiY
A5: BDwbU-2 (Kz`ve, c~evBj, MvRxcyi) | O5: ZvwiLt 02.08.2026
A6: µ: | B6: ‡kÖbx | C6: jU bs | D6: jU msL¨v | E6: ‡gvU eB | F6: wcÖw›Us (B‡¤úªkb) | I6: wcÖw›Us (eB) | K6: evBwÛs | M6: ‡Wwjfvix | O6: ÷K eB | P6: Kv‡Ri nvi-% | S6: ‡Wwjfvix †kl ZvwiL
F7: ‡gvU B‡¤úªkb | G7: wcÖw›Us | H7: evwK | I7: wcÖw›Us (eB) | J7: evwK | K7: evBwÛs | L7: evwK | M7: ‡Wwjfvix | N7: evwK | P7: wcÖw›Us | Q7: evBwÛs | R7: ‡Wwjfvix
A8: 1 | B8: wcÖ-cÖvBgvix | C8: 123 | D8: Avgvi eB | E8: ='MSPL-2 (Class)'!K7 -> 66398 | F8: ='MSPL-2 (Class)'!R7 -> 713778.5 | G8: ='Top Sheet-(Class)'!L8 -> 0 | H8: =F8-G8 -> 713778.5 | I8: ='Top Sheet-(Class)'!N8 -> 0 | J8: =E8-I8 -> 66398 | K8: ='Top Sheet-(Class)'!P8 -> 0 | L8: =E8-K8 -> 66398 | M8: ='Top Sheet-(Class)'!R8 -> 0 | N8: =E8-M8 -> 66398 | O8: =K8-M8 -> 0 | P8: =G8/F8% -> 0 | Q8: =K8/E8% -> 0 | R8: =M8/E8% -> 0
D9: LvZv | E9: ='MSPL-2 (Class)'!K8 -> 66398 | F9: ='MSPL-2 (Class)'!R8 -> 564383 | G9: ='Top Sheet-(Class)'!L9 -> 0 | H9: =F9-G9 -> 564383 | I9: ='Top Sheet-(Class)'!N9 -> 0 | J9: =E9-I9 -> 66398 | K9: ='Top Sheet-(Class)'!P9 -> 0 | L9: =E9-K9 -> 66398 | M9: ='Top Sheet-(Class)'!R9 -> 0 | N9: =E9-M9 -> 66398 | O9: =K9-M9 -> 0 | P9: =G9/F9% -> 0 | Q9: =K9/E9% -> 0 | R9: =M9/E9% -> 0
A10: 2 | B10: cÖvBgvix | C10: 329- 338-347-375-401 | D10: 5wU | E10: ='MSPL-2 (Class)'!K70 -> 4031896 | F10: ='MSPL-2 (Class)'!R70 -> 31161631 | G10: ='Top Sheet-(Class)'!L10 -> 0 | H10: =F10-G10 -> 31161631 | I10: ='Top Sheet-(Class)'!N10 -> 0 | J10: =E10-I10 -> 4031896 | K10: ='Top Sheet-(Class)'!P10 -> 0 | L10: =E10-K10 -> 4031896 | M10: ='Top Sheet-(Class)'!R10 -> 0 | N10: =E10-M10 -> 4031896 | O10: =K10-M10 -> 0 | P10: =G10/F10% -> 0 | Q10: =K10/E10% -> 0 | R10: =M10/E10% -> 0
A11: 3 | B11: 7g | C11: 706-708-757-759-762 | D11: 5wU | E11: ='MSPL-2 (Class)'!K102 -> 2188607 | F11: ='MSPL-2 (Class)'!R102 -> 9928182.2 | G11: ='Top Sheet-(Class)'!L11 -> 0 | H11: =F11-G11 -> 9928182.2 | I11: ='Top Sheet-(Class)'!N11 -> 0 | J11: =E11-I11 -> 2188607 | K11: ='Top Sheet-(Class)'!P11 -> 0 | L11: =E11-K11 -> 2188607 | M11: ='Top Sheet-(Class)'!R11 -> 0 | N11: =E11-M11 -> 2188607 | O11: =K11-M11 -> 0 | P11: =G11/F11% -> 0 | Q11: =K11/E11% -> 0 | R11: =M11/E11% -> 0
A12: 4 | B12: beg-mvwnZ¨ | C12: 926-938-953-963 | D12: 4wU | E12: ='MSPL-2 (Class)'!K131 -> 1246343 | F12: ='MSPL-2 (Class)'!R131 -> 9731784.8 | G12: ='Top Sheet-(Class)'!L12 -> 0 | H12: =F12-G12 -> 9731784.8 | I12: ='Top Sheet-(Class)'!N12 -> 0 | J12: =E12-I12 -> 1246343 | K12: ='Top Sheet-(Class)'!P12 -> 0 | L12: =E12-K12 -> 1246343 | M12: ='Top Sheet-(Class)'!R12 -> 0 | N12: =E12-M12 -> 1246343 | O12: =K12-M12 -> 0 | P12: =G12/F12% -> 0 | Q12: =K12/E12% -> 0 | R12: =M12/E12% -> 0
A13: 5 | B13: beg-Kvjvi | C13: 1122 | D13: 1wU | E13: ='MSPL-2 (Class)'!K159 -> 295274 | F13: ='MSPL-2 (Class)'!R159 -> 4708344.5 | G13: ='Top Sheet-(Class)'!L13 -> 0 | H13: =F13-G13 -> 4708344.5 | I13: ='Top Sheet-(Class)'!N13 -> 0 | J13: =E13-I13 -> 295274 | K13: ='Top Sheet-(Class)'!P13 -> 0 | L13: =E13-K13 -> 295274 | M13: ='Top Sheet-(Class)'!R13 -> 0 | N13: =E13-M13 -> 295274 | O13: =K13-M13 -> 0 | P13: =G13/F13% -> 0 | Q13: =K13/E13% -> 0 | R13: =M13/E13% -> 0
A14: 6 | B14: beg-`vwLj | C14: 1055 | D14: 1wU | E14: ='MSPL-2 (Class)'!K206 -> 287460 | F14: ='MSPL-2 (Class)'!R206 -> 2363805 | G14: ='Top Sheet-(Class)'!L14 -> 0 | H14: =F14-G14 -> 2363805 | I14: ='Top Sheet-(Class)'!N14 -> 0 | J14: =E14-I14 -> 287460 | K14: ='Top Sheet-(Class)'!P14 -> 0 | L14: =E14-K14 -> 287460 | M14: ='Top Sheet-(Class)'!R14 -> 0 | N14: =E14-M14 -> 287460 | O14: =K14-M14 -> 0 | P14: =G14/F14% -> 0 | Q14: =K14/E14% -> 0 | R14: =M14/E14% -> 0
A15: me©‡gvU | D15: 17 wU | E15: =SUM(E8:E14) -> 8182376 | F15: =SUM(F8:F14) -> 59171909 | G15: =SUM(G8:G14) -> 0 | H15: =SUM(H8:H14) -> 59171909 | I15: =SUM(I8:I14) -> 0 | J15: =SUM(J8:J14) -> 8182376 | K15: =SUM(K8:K14) -> 0 | L15: =SUM(L8:L14) -> 8182376 | ... S15: =SUM(S8:S14) -> 0
A17: BDwbU-3 (Qbcvov, AvovBnvRvi, bvivqbMÄ)
A18: µ: | B18: ‡kÖbx | C18: jU bs | D18: jU msL¨v | E18: ‡gvU eB | F18: wcÖw›Us (B‡¤úªkb) | I18: wcÖw›Us (eB) | K18: evBwÛs | M18: ‡Wwjfvix | O18: ÷K eB | P18: Kv‡Ri nvi-% | S18: ‡Wwjfvix †kl ZvwiL
F19: ‡gvU B‡¤úªkb | G19: wcÖw›Us | H19: evwK | I19: wcÖw›Us (eB) | J19: evwK | K19: evBwÛs | L19: evwK | M19: ‡Wwjfvix | N19: evwK | P19: wcÖw›Us | Q19: evBwÛs | R19: ‡Wwjfvix
A20: 1 | B20: cÖvBgvix | C20: 376379 | D20: 2wU | E20: ='MSPL-3(Class)'!L34 -> 1396833 | F20: ='MSPL-3(Class)'!N34 -> 10754081 | G20: ='Top Sheet-(Class)'!L20 -> 0 | H20: =F20-G20 -> 10754081 | I20: ='Top Sheet-(Class)'!N20 -> 0 | J20: =E20-I20 -> 1396833 | K20: ='Top Sheet-(Class)'!P20 -> 0 | L20: =E20-K20 -> 1396833 | M20: ='Top Sheet-(Class)'!R20 -> 0 | N20: =E20-M20 -> 1396833 | O20: =K20-M20 -> 0 | P20: =G20/F20% -> 0 | Q20: =K20/E20% -> 0 | R20: =M20/E20% -> 0
A21: 2 | B21: Be‡Z`vqx | C21: 2022 | D21: 1wU | E21: ='MSPL-3(Class)'!L64 -> 862368 | F21: ='MSPL-3(Class)'!N64 -> 4873221.8 | G21: ='Top Sheet-(Class)'!L21 -> 0 | H21: =F21-G21 -> 4873221.8 | I21: ='Top Sheet-(Class)'!N21 -> 0 | J21: =E21-I21 -> 862368 | K21: ='Top Sheet-(Class)'!P21 -> 0 | L21: =E21-K21 -> 862368 | M21: ='Top Sheet-(Class)'!R21 -> 0 | N21: =E21-M21 -> 862368 | O21: =K21-M21 -> 0 | P21: =G21/F21% -> 0 | Q21: =K21/E21% -> 0 | R21: =M21/E21% -> 0
A22: 3 | B22: 6ô gva¨wgK | C22: 646 | D22: 1wU | E22: ='MSPL-3(Class)'!L102 -> 407322 | F22: ='MSPL-3(Class)'!N102 -> 1567424.8 | G22: ='Top Sheet-(Class)'!L22 -> 0 | H22: =F22-G22 -> 1567424.8 | I22: ='Top Sheet-(Class)'!N22 -> 0 | J22: =E22-I22 -> 407322 | K22: ='Top Sheet-(Class)'!P22 -> 0 | L22: =E22-K22 -> 407322 | M22: ='Top Sheet-(Class)'!R22 -> 0 | N22: =E22-M22 -> 407322 | O22: =K22-M22 -> 0 | P22: =G22/F22% -> 0 | Q22: =K22/E22% -> 0 | R22: =M22/E22% -> 0
A23: 4 | B23: 6ô `vwLj | C23: 667 | D23: 1wU | E23: ='MSPL-3(Class)'!L133 -> 693254 | F23: ='MSPL-3(Class)'!N133 -> 2768978.5 | G23: ='Top Sheet-(Class)'!L23 -> 0 | H23: =F23-G23 -> 2768978.5 | I23: ='Top Sheet-(Class)'!N23 -> 0 | J23: =E23-I23 -> 693254 | K23: ='Top Sheet-(Class)'!P23 -> 0 | L23: =E23-K23 -> 693254 | M23: ='Top Sheet-(Class)'!R23 -> 0 | N23: =E23-M23 -> 693254 | O23: =K23-M23 -> 0 | P23: =G23/F23% -> 0 | Q23: =K23/E23% -> 0 | R23: =M23/E23% -> 0
A24: 5 | B24: 8g gva¨wgK | C24: 834-843-854-865-872-877 | D24: 6wU | E24: ='MSPL-3(Class)'!L177 -> 2933769 | F24: ='MSPL-3(Class)'!N177 -> 14405581 | G24: ='Top Sheet-(Class)'!L24 -> 0 | H24: =F24-G24 -> 14405581 | I24: ='Top Sheet-(Class)'!N24 -> 0 | J24: =E24-I24 -> 2933769 | K24: ='Top Sheet-(Class)'!P24 -> 0 | L24: =E24-K24 -> 2933769 | M24: ='Top Sheet-(Class)'!R24 -> 0 | N24: =E24-M24 -> 2933769 | O24: =K24-M24 -> 0 | P24: =G24/F24% -> 0 | Q24: =K24/E24% -> 0 | R24: =M24/E24% -> 0
A25: me©‡gvU | D25: 11wU | E25: =SUM(E20:E24) -> 6293546 | F25: =SUM(F20:F24) -> 34369287 | G25: =SUM(G20:G24) -> 0 | H25: =SUM(H20:H24) -> 34369287 | I25: =SUM(I20:I24) -> 0 | J25: =SUM(J20:J24) -> 6293546 | K25: =SUM(K20:K24) -> 0 | L25: =SUM(L20:L24) -> 6293546 | ... O25: =SUM(O20:O24) -> 0 | P25: =G25/F25% -> 0 | Q25: =K25/E25% -> 0 | R25: =M25/E25% -> 0 | S25: =SUM(S20:S24) -> 0
A27: BDwbU-2 Ges BDwbU-3 me©‡gvU | D27: 28wU | E27: =E25+E15 -> 14475922 | F27: =F25+F15 -> 93541196 | G27: =G25+G15 -> 0 | H27: =H25+H15 -> 93541196 | I27: =I25+I15 -> 0 | J27: =J25+J15 -> 14475922 | K27: =K25+K15 -> 0 | L27: =L25+L15 -> 14475922 | ... O27: =O25+O15 -> 0 | P27: =G27/F27% -> 0 | Q27: =K27/E27% -> 0 | R27: =M27/E27% -> 0 | S27: =S25+S15 -> 0

Sheet Top Sheet-(Class)
A1: gvóvi wm‡g· †ccvi wjt
A2: Kz`ve, c~evBj, MvRxcyi (BDwbU-2) Qbcvov, AvovBnvRvi, bvivqbMÄ (&BDwbU-3)
A3: RvZxq wkÿvµg I cvV¨cy¯ÍK †evW© Gi 2027 wkÿve‡l©i cvV¨cy¯ÍK (gy`ªY, evavuB, mieivn) Kv‡Ri weeiY
A5: BDwbU-2 (Kz`ve, c~evBj, MvRxcyi)
A6: µ: | B6: ‡kÖbx | C6: jU bs | D6: jU msL¨v | E6: ‡gvU eB | F6: ‡cøU Pvwn`v | I6: Kfvi | K6: wcÖw›Us (B‡¤úªkb) | N6: wcÖw›Us (eB) | P6: evBwÛs | R6: ‡Wwjfvix | T6: ÷K eB | U6: ‡ccvi | Y6: evBwÛs Gi Rb¨ A‡cÿgvb | Z6: Kv‡Ri nvi-% | AC6: ‡Wwjfvix †kl ZvwiL
F7: Pvwn`v | G7: wiwmf | H7: evwK | I7: wiwmf | J7: evwK | K7: ‡gvU B‡¤úªkb | L7: wcÖw›Us | M7: evwK | N7: wcÖw›Us (eB) | O7: evwK | P7: evBwÛs | Q7: evwK | R7: ‡Wwjfvix | S7: evwK | U7: wig | V7: Ub | W7: e¨envi | X7: evwK | Z7: wcÖw›Us | AA7: evBwÛs | AB7: ‡Wwjfvix
A8: 1 | B8: wcÖ-cÖvBgvix | C8: 123 | D8: Avgvi eB | E8: ='MSPL-2 (Class)'!K7 -> 66398 | F8: ='MSPL-2 (Class)'!M7 -> 192 | G8: ='MSPL-2 (Class)'!N7 -> 0 | H8: ='MSPL-2 (Class)'!O7 -> 192 | I8: ='MSPL-2 (Class)'!P7 -> 0 | J8: ='MSPL-2 (Class)'!Q7 -> 66398 | K8: ='MSPL-2 (Class)'!R7 -> 713778.5 | L8: ='MSPL-2 (Class)'!S7 -> 0 | M8: ='MSPL-2 (Class)'!T7 -> 713778.5 | ... T8: ='MSPL-2 (Class)'!AA7 -> 0 | U8: ='MSPL-2 (Class)'!AD7 -> 1427.557 | V8: ='MSPL-2 (Class)'!AE7 -> 28.55114 | W8: ='MSPL-2 (Class)'!AF7 -> 0 | X8: ='MSPL-2 (Class)'!AG7 -> 28.55114 | Y8: ='MSPL-2 (Class)'!AC7 -> 0 | Z8: =L8/K8% -> 0 | AA8: =P8/E8% -> 0 | AB8: =R8/E8% -> 0
D9: LvZv | E9: ='MSPL-2 (Class)'!K8 -> 66398 | F9: ='MSPL-2 (Class)'!M8 -> 18 | G9: ='MSPL-2 (Class)'!N8 -> 0 | H9: ='MSPL-2 (Class)'!O8 -> 18 | I9: ='MSPL-2 (Class)'!P8 -> 0 | J9: ='MSPL-2 (Class)'!Q8 -> 66398 | K9: ='MSPL-2 (Class)'!R8 -> 564383 | L9: ='MSPL-2 (Class)'!S8 -> 0 | M9: ='MSPL-2 (Class)'!T8 -> 564383 | ... T9: ='MSPL-2 (Class)'!AA8 -> 0 | U9: ='MSPL-2 (Class)'!AD8 -> 1128.766 | V9: ='MSPL-2 (Class)'!AE8 -> 17.365631 | W9: ='MSPL-2 (Class)'!AF8 -> 0 | X9: ='MSPL-2 (Class)'!AG8 -> 17.365631 | Y9: ='MSPL-2 (Class)'!AC8 -> 0 | Z9: =L9/K9% -> 0 | AA9: =P9/E9% -> 0 | AB9: =R9/E9% -> 0
A10: 2 | B10: cÖvBgvix | C10: 329338347375401 | D10: 5wU | E10: ='MSPL-2 (Class)'!K70 -> 4031896 | F10: ='MSPL-2 (Class)'!M70 -> 4856 | G10: ='MSPL-2 (Class)'!N70 -> 0 | H10: ='MSPL-2 (Class)'!O70 -> 4856 | I10: ='MSPL-2 (Class)'!P70 -> 0 | J10: ='MSPL-2 (Class)'!Q70 -> 4031896 | K10: ='MSPL-2 (Class)'!R70 -> 31161631 | L10: ='MSPL-2 (Class)'!S70 -> 0 | M10: ='MSPL-2 (Class)'!T70 -> 31161631 | ... T10: ='MSPL-2 (Class)'!AA70 -> 0 | U10: ='MSPL-2 (Class)'!AD70 -> 62323.261 | V10: ='MSPL-2 (Class)'!AE70 -> 958.81941 | W10: ='MSPL-2 (Class)'!AF70 -> 0 | X10: ='MSPL-2 (Class)'!AG70 -> 958.81941 | Y10: ='MSPL-2 (Class)'!AC70 -> 0 | Z10: =L10/K10% -> 0 | AA10: =P10/E10% -> 0 | AB10: =R10/E10% -> 0
A11: 3 | B11: 7g | C11: 706708757759762 | D11: 5wU | E11: ='MSPL-2 (Class)'!K102 -> 2188607 | F11: ='MSPL-2 (Class)'!M102 -> 792 | G11: ='MSPL-2 (Class)'!N102 -> 0 | H11: ='MSPL-2 (Class)'!O102 -> 792 | I11: ='MSPL-2 (Class)'!P102 -> 0 | J11: ='MSPL-2 (Class)'!Q102 -> 2188607 | K11: ='MSPL-2 (Class)'!R102 -> 9928182.2 | L11: ='MSPL-2 (Class)'!S102 -> 0 | M11: ='MSPL-2 (Class)'!T102 -> 9928182.2 | ... T11: ='MSPL-2 (Class)'!AA102 -> 0 | U11: ='MSPL-2 (Class)'!AD102 -> 34834.248 | V11: ='MSPL-2 (Class)'!AE102 -> 464.45663 | W11: ='MSPL-2 (Class)'!AF102 -> 0 | X11: ='MSPL-2 (Class)'!AG102 -> 464.45663 | Y11: ='MSPL-2 (Class)'!AC102 -> 0 | Z11: =L11/K11% -> 0 | AA11: =P11/E11% -> 0 | AB11: =R11/E11% -> 0
A12: 4 | B12: beg-mvwnZ¨ | C12: 926938953963 | D12: 4wU | E12: ='MSPL-2 (Class)'!K131 -> 1246343 | F12: ='MSPL-2 (Class)'!M131 -> 752 | G12: ='MSPL-2 (Class)'!N131 -> 0 | H12: ='MSPL-2 (Class)'!O131 -> 752 | I12: ='MSPL-2 (Class)'!P131 -> 0 | J12: ='MSPL-2 (Class)'!Q131 -> 1246343 | K12: ='MSPL-2 (Class)'!R131 -> 9731784.8 | L12: ='MSPL-2 (Class)'!S131 -> 0 | M12: ='MSPL-2 (Class)'!T131 -> 9731784.8 | ... T12: ='MSPL-2 (Class)'!AA131 -> 0 | U12: ='MSPL-2 (Class)'!AD131 -> 37139.76 | V12: ='MSPL-2 (Class)'!AE131 -> 495.19679 | W12: ='MSPL-2 (Class)'!AF131 -> 0 | X12: ='MSPL-2 (Class)'!AG131 -> 495.19679 | Y12: ='MSPL-2 (Class)'!AC131 -> 0 | Z12: =L12/K12% -> 0 | AA12: =P12/E12% -> 0 | AB12: =R12/E12% -> 0
A13: 5 | B13: beg-Kvjvi | C13: 1122 | D13: 1wU | E13: ='MSPL-2 (Class)'!K159 -> 295274 | F13: ='MSPL-2 (Class)'!M159 -> 1400 | G13: ='MSPL-2 (Class)'!N159 -> 0 | H13: ='MSPL-2 (Class)'!O159 -> 1400 | I13: ='MSPL-2 (Class)'!P159 -> 0 | J13: ='MSPL-2 (Class)'!Q159 -> 295274 | K13: ='MSPL-2 (Class)'!R159 -> 4708344.5 | L13: ='MSPL-2 (Class)'!S159 -> 0 | M13: ='MSPL-2 (Class)'!T159 -> 4708344.5 | ... T13: ='MSPL-2 (Class)'!AA159 -> 0 | U13: ='MSPL-2 (Class)'!AD159 -> 9416.689 | V13: ='MSPL-2 (Class)'!AE159 -> 125.55585 | W13: ='MSPL-2 (Class)'!AF159 -> 0 | X13: ='MSPL-2 (Class)'!AG159 -> 125.55585 | Y13: ='MSPL-2 (Class)'!AC159 -> 0 | Z13: =L13/K13% -> 0 | AA13: =P13/E13% -> 0 | AB13: =R13/E13% -> 0
A14: 6 | B14: beg-`vwLj | C14: 1055 | D14: 1wU | E14: ='MSPL-2 (Class)'!K206 -> 287460 | F14: ='MSPL-2 (Class)'!M206 -> 578 | G14: ='MSPL-2 (Class)'!N206 -> 0 | H14: ='MSPL-2 (Class)'!O206 -> 578 | I14: ='MSPL-2 (Class)'!P206 -> 0 | J14: ='MSPL-2 (Class)'!Q206 -> 287460 | K14: ='MSPL-2 (Class)'!R206 -> 2363805 | L14: ='MSPL-2 (Class)'!S206 -> 0 | M14: ='MSPL-2 (Class)'!T206 -> 2363805 | ... T14: ='MSPL-2 (Class)'!AA206 -> 0 | U14: ='MSPL-2 (Class)'!AD206 -> 8915.73 | V14: ='MSPL-2 (Class)'!AE206 -> 118.8764 | W14: ='MSPL-2 (Class)'!AF206 -> 0 | X14: ='MSPL-2 (Class)'!AG206 -> 118.8764 | Y14: ='MSPL-2 (Class)'!AC206 -> 0 | Z14: =L14/K14% -> 0 | AA14: =P14/E14% -> 0 | AB14: =R14/E14% -> 0
A15: me©‡gvU | D15: 17 wU | E15: =SUM(E8:E14) -> 8182376 | F15: =SUM(F8:F14) -> 8588 | G15: =SUM(G8:G14) -> 0 | H15: =SUM(H8:H14) -> 8588 | I15: =SUM(I8:I14) -> 0 | J15: =SUM(J8:J14) -> 8182376 | K15: =SUM(K8:K14) -> 59171909 | L15: =SUM(L8:L14) -> 0 | ... AC15: =SUM(AC8:AC14) -> 0
A17: BDwbU-3 (Qbcvov, AvovBnvRvi, bvivqbMÄ)
A18: µ: | B18: ‡kÖbx | C18: jU bs | D18: jU msL¨v | E18: ‡gvU eB | F18: ‡cøU Pvwn`v | I18: Kfvi | K18: wcÖw›Us (B‡¤úªkb) | N18: wcÖw›Us (eB) | P18: evBwÛs | R18: ‡Wwjfvix | T18: ÷K eB | U18: ‡ccvi | Y18: evBwÛs Gi Rb¨ A‡cÿgvb | Z18: Kv‡Ri nvi-% | AC18: ‡Wwjfvix †kl ZvwiL
F19: Pvwn`v | G19: wiwmf | H19: evwK | I19: wiwmf | J19: evwK | K19: ‡gvU B‡¤úªkb | L19: wcÖw›Us | M19: evwK | N19: wcÖw›Us (eB) | O19: evwK | P19: evBwÛs | Q19: evwK | R19: ‡Wwjfvix | S19: evwK | U19: wig | V19: Ub | W19: e¨envi | X19: evwK | Z19: wcÖw›Us | AA19: evBwÛs | AB19: ‡Wwjfvix
A20: 1 | B20: cÖvBgvix | C20: 376379 | D20: 2wU | E20: ='MSPL-3(Class)'!L34 -> 1396833 | K20: ='MSPL-3(Class)'!N34 -> 10754081 | L20: ='MSPL-3(Class)'!O34 -> 0 | M20: ='MSPL-3(Class)'!P34 -> 10754081 | N20: ='MSPL-3(Class)'!Q34 -> 0 | O20: ='MSPL-3(Class)'!R34 -> 1396833 | P20: ='MSPL-3(Class)'!S34 -> 0 | Q20: ='MSPL-3(Class)'!T34 -> 1396833 | R20: ='MSPL-3(Class)'!U34 -> 0 | ... T20: ='MSPL-3(Class)'!W34 -> 0 | U20: ='MSPL-3(Class)'!Z34 -> 21508.162 | V20: ='MSPL-3(Class)'!AA34 -> 330.8948 | W20: ='MSPL-3(Class)'!AB34 -> 0 | X20: ='MSPL-3(Class)'!AC34 -> 330.8948 | Y20: ='MSPL-3(Class)'!Y34 -> 0 | Z20: =L20/K20% -> 0 | AA20: =P20/E20% -> 0 | AB20: =R20/E20% -> 0
A21: 2 | B21: Be‡Z`vqx | C21: 2022 | D21: 1wU | E21: ='MSPL-3(Class)'!L64 -> 862368 | K21: ='MSPL-3(Class)'!N64 -> 4873221.8 | L21: ='MSPL-3(Class)'!O64 -> 0 | M21: ='MSPL-3(Class)'!P64 -> 4873221.8 | N21: ='MSPL-3(Class)'!Q64 -> 0 | O21: ='MSPL-3(Class)'!R64 -> 862368 | P21: ='MSPL-3(Class)'!S64 -> 0 | Q21: ='MSPL-3(Class)'!T64 -> 862368 | R21: ='MSPL-3(Class)'!U64 -> 0 | ... T21: ='MSPL-3(Class)'!W64 -> 0 | U21: ='MSPL-3(Class)'!Z64 -> 9746.4435 | V21: ='MSPL-3(Class)'!AA64 -> 149.94528 | W21: ='MSPL-3(Class)'!AB64 -> 0 | X21: ='MSPL-3(Class)'!AC64 -> 149.94528 | Y21: ='MSPL-3(Class)'!Y64 -> 0 | Z21: =L21/K21% -> 0 | AA21: =P21/E21% -> 0 | AB21: =R21/E21% -> 0
A22: 3 | B22: 6ô gva¨wgK | C22: 646 | D22: 1wU | E22: ='MSPL-3(Class)'!L102 -> 407322 | K22: ='MSPL-3(Class)'!N102 -> 1567424.8 | L22: ='MSPL-3(Class)'!O102 -> 0 | M22: ='MSPL-3(Class)'!P102 -> 1567424.8 | N22: ='MSPL-3(Class)'!Q102 -> 0 | O22: ='MSPL-3(Class)'!R102 -> 407322 | P22: ='MSPL-3(Class)'!S102 -> 0 | Q22: ='MSPL-3(Class)'!T102 -> 407322 | R22: ='MSPL-3(Class)'!U102 -> 0 | ... T22: ='MSPL-3(Class)'!W102 -> 0 | U22: ='MSPL-3(Class)'!Z102 -> 5418.2295 | V22: ='MSPL-3(Class)'!AA102 -> 72.24306 | W22: ='MSPL-3(Class)'!AB102 -> 0 | X22: ='MSPL-3(Class)'!AC102 -> 72.24306 | Y22: ='MSPL-3(Class)'!Y102 -> 0 | Z22: =L22/K22% -> 0 | AA22: =P22/E22% -> 0 | AB22: =R22/E22% -> 0
A23: 4 | B23: 6ô `vwLj | C23: 667 | D23: 1wU | E23: ='MSPL-3(Class)'!L133 -> 693254 | K23: ='MSPL-3(Class)'!N133 -> 2768978.5 | L23: ='MSPL-3(Class)'!O133 -> 0 | M23: ='MSPL-3(Class)'!P133 -> 2768978.5 | N23: ='MSPL-3(Class)'!Q133 -> 0 | O23: ='MSPL-3(Class)'!R133 -> 693254 | P23: ='MSPL-3(Class)'!S133 -> 0 | Q23: ='MSPL-3(Class)'!T133 -> 693254 | R23: ='MSPL-3(Class)'!U133 -> 0 | ... T23: ='MSPL-3(Class)'!W133 -> 0 | U23: ='MSPL-3(Class)'!Z133 -> 10012.573 | V23: ='MSPL-3(Class)'!AA133 -> 133.50097 | W23: ='MSPL-3(Class)'!AB133 -> 0 | X23: ='MSPL-3(Class)'!AC133 -> 133.50097 | Y23: ='MSPL-3(Class)'!Y133 -> 0 | Z23: =L23/K23% -> 0 | AA23: =P23/E23% -> 0 | AB23: =R23/E23% -> 0
A24: 5 | B24: 8g gva¨wgK | C24: 834-843-854-865-872-877 | D24: 6wU | E24: ='MSPL-3(Class)'!L177 -> 2933769 | K24: ='MSPL-3(Class)'!N177 -> 14405581 | L24: ='MSPL-3(Class)'!O177 -> 0 | M24: ='MSPL-3(Class)'!P177 -> 14405581 | N24: ='MSPL-3(Class)'!Q177 -> 0 | O24: ='MSPL-3(Class)'!R177 -> 2933769 | P24: ='MSPL-3(Class)'!S177 -> 0 | Q24: ='MSPL-3(Class)'!T177 -> 2933769 | R24: ='MSPL-3(Class)'!U177 -> 0 | ... T24: ='MSPL-3(Class)'!W177 -> 0 | U24: ='MSPL-3(Class)'!Z177 -> 53170.316 | V24: ='MSPL-3(Class)'!AA177 -> 708.93755 | W24: ='MSPL-3(Class)'!AB177 -> 0 | X24: ='MSPL-3(Class)'!AC177 -> 708.93755 | Y24: ='MSPL-3(Class)'!Y177 -> 0 | Z24: =L24/K24% -> 0 | AA24: =P24/E24% -> 0 | AB24: =R24/E24% -> 0
A25: me©‡gvU | D25: 11wU | E25: =SUM(E20:E24) -> 6293546 | K25: =SUM(K20:K24) -> 34369287 | L25: =SUM(L20:L24) -> 0 | M25: =SUM(M20:M24) -> 34369287 | N25: =SUM(N20:N24) -> 0 | O25: =SUM(O20:O24) -> 6293546 | P25: =SUM(P20:P24) -> 0 | Q25: =SUM(Q20:Q24) -> 6293546 | R25: =SUM(R20:R24) -> 0 | ... Y25: =SUM(Y20:Y24) -> 0 | Z25: =L25/K25% -> 0 | AA25: =P25/E25% -> 0 | AB25: =R25/E25% -> 0
A27: BDwbU-2 Ges BDwbU-3 me©‡gvU | D27: 28wU | E27: =E15+E25 -> 14475922 | F27: =F15+F25 -> 8588 | G27: =G15+G25 -> 0 | H27: =H15+H25 -> 8588 | I27: =I15+I25 -> 0 | J27: =J15+J25 -> 8182376 | K27: =K15+K25 -> 93541196 | L27: =L15+L25 -> 0 | ... Y27: =Y15+Y25 -> 0 | Z27: =L27/K27% -> 0 | AA27: =P27/E27% -> 0 | AB27: =R27/E27% -> 0

Sheet Top Sheet-(Lot)
A1: gvóvi wm‡g· †ccvi wjt
A2: Kz`ve, c~evBj, MvRxcyi (BDwbU-2) Qbcvov, AvovBnvRvi, bvivqbMÄ (&BDwbU-3)
A3: RvZxq wkÿvµg I cvV¨cy¯ÍK †evW© Gi 2027 wkÿve‡l©i cvV¨cy¯ÍK (gy`ªY, evavuB, mieivn) Kv‡Ri weeiY
A5: BDwbU-2 (Kz`ve, c~evBj, MvRxcyi) | R5: ZvwiL: 03/08/2026
A6: µ: | B6: ‡kÖbx | C6: jU msL¨v | D6: ‡gvU eB | E6: wcÖw›Us (B‡¤úªkb) | H6: wcÖw›Us (eB) | J6: evBwÛs | L6: ‡Wwjfvix | N6: ÷K eB | O6: Kv‡Ri nvi-% | R6: ‡Wwjfvix †kl ZvwiL | S6: ‡ccvi
E7: ‡gvU B‡¤úªkb | F7: wcÖw›Us | G7: evwK | H7: wcÖw›Us (eB) | I7: evwK | J7: evBwÛs | K7: evwK | L7: ‡Wwjfvix | M7: evwK | O7: wcÖw›Us | P7: evBwÛs | Q7: ‡Wwjfvix | S7: wig | T7: Ub | U7: e¨envi | V7: evwK
A8: 1 | B8: wcÖ-cÖvBgvix | C8: Avgvi eB | D8: ='MSPL-2(LOT)'!E7 -> 66398 | E8: ='MSPL-2(LOT)'!G7 -> 713778.5 | F8: ='MSPL-2(LOT)'!H7 -> 0 | G8: ='MSPL-2(LOT)'!I7 -> 713778.5 | H8: ='MSPL-2(LOT)'!J7 -> 0 | I8: ='MSPL-2(LOT)'!K7 -> 66398 | J8: ='MSPL-2(LOT)'!L7 -> 0 | K8: ='MSPL-2(LOT)'!M7 -> 66398 | L8: ='MSPL-2(LOT)'!N7 -> 0 | ... N8: ='MSPL-2(LOT)'!P7 -> 0 | O8: =F8/E8% -> 0 | P8: =J8/D8% -> 0 | Q8: =L8/D8% -> 0 | S8: ='MSPL-2(LOT)'!R7 -> 1427.557 | T8: ='MSPL-2(LOT)'!S7 -> 28.55114 | U8: ='MSPL-2(LOT)'!T7 -> 0 | V8: ='MSPL-2(LOT)'!U7 -> 28.55114
C9: LvZv | D9: ='MSPL-2(LOT)'!E8 -> 66398 | E9: ='MSPL-2(LOT)'!G8 -> 564383 | F9: ='MSPL-2(LOT)'!H8 -> 0 | G9: ='MSPL-2(LOT)'!I8 -> 564383 | H9: ='MSPL-2(LOT)'!J8 -> 0 | I9: ='MSPL-2(LOT)'!K8 -> 66398 | J9: ='MSPL-2(LOT)'!L8 -> 0 | K9: ='MSPL-2(LOT)'!M8 -> 66398 | L9: ='MSPL-2(LOT)'!N8 -> 0 | ... N9: ='MSPL-2(LOT)'!P8 -> 0 | O9: =F9/E9% -> 0 | P9: =J9/D9% -> 0 | Q9: =L9/D9% -> 0 | S9: ='MSPL-2(LOT)'!R8 -> 1128.766 | T9: ='MSPL-2(LOT)'!S8 -> 17.365631 | U9: ='MSPL-2(LOT)'!T8 -> 0 | V9: ='MSPL-2(LOT)'!U8 -> 17.365631
A10: 2 | B10: cÖvBgvix | C10: 329 | D10: ='MSPL-2(LOT)'!E67 -> 834870 | E10: ='MSPL-2(LOT)'!G67 -> 6422471 | F10: ='MSPL-2(LOT)'!H67 -> 0 | G10: ='MSPL-2(LOT)'!I67 -> 6422471 | H10: ='MSPL-2(LOT)'!J67 -> 0 | I10: ='MSPL-2(LOT)'!K67 -> 834870 | J10: ='MSPL-2(LOT)'!L67 -> 0 | K10: ='MSPL-2(LOT)'!M67 -> 834870 | L10: ='MSPL-2(LOT)'!N67 -> 0 | ... N10: ='MSPL-2(LOT)'!P67 -> 0 | O10: =F10/E10% -> 0 | P10: =J10/D10% -> 0 | Q10: =L10/D10% -> 0 | S10: ='MSPL-2(LOT)'!R67 -> 12844.942 | T10: ='MSPL-2(LOT)'!S67 -> 197.61449 | U10: ='MSPL-2(LOT)'!T67 -> 0 | V10: ='MSPL-2(LOT)'!U67 -> 197.61449
C11: 338 | D11: ='MSPL-2(LOT)'!E104 -> 806057 | E11: ='MSPL-2(LOT)'!G104 -> 6232721 | F11: ='MSPL-2(LOT)'!H104 -> 0 | G11: ='MSPL-2(LOT)'!I104 -> 6232721 | H11: ='MSPL-2(LOT)'!J104 -> 0 | I11: ='MSPL-2(LOT)'!K104 -> 806057 | J11: ='MSPL-2(LOT)'!L104 -> 0 | K11: ='MSPL-2(LOT)'!M104 -> 806057 | L11: ='MSPL-2(LOT)'!N104 -> 0 | ... N11: ='MSPL-2(LOT)'!P104 -> 0 | O11: =F11/E11% -> 0 | P11: =J11/D11% -> 0 | Q11: =L11/D11% -> 0 | S11: ='MSPL-2(LOT)'!R104 -> 12465.442 | T11: ='MSPL-2(LOT)'!S104 -> 191.77603 | U11: ='MSPL-2(LOT)'!T104 -> 0 | V11: ='MSPL-2(LOT)'!U104 -> 191.77603
C12: 347 | D12: ='MSPL-2(LOT)'!E141 -> 874367 | E12: ='MSPL-2(LOT)'!G141 -> 6737695.2 | F12: ='MSPL-2(LOT)'!H141 -> 0 | G12: ='MSPL-2(LOT)'!I141 -> 6737695.2 | H12: ='MSPL-2(LOT)'!J141 -> 0 | I12: ='MSPL-2(LOT)'!K141 -> 874367 | J12: ='MSPL-2(LOT)'!L141 -> 0 | K12: ='MSPL-2(LOT)'!M141 -> 874367 | L12: ='MSPL-2(LOT)'!N141 -> 0 | ... N12: ='MSPL-2(LOT)'!P141 -> 0 | O12: =F12/E12% -> 0 | P12: =J12/D12% -> 0 | Q12: =L12/D12% -> 0 | S12: ='MSPL-2(LOT)'!R141 -> 13475.391 | T12: ='MSPL-2(LOT)'!S141 -> 207.3137 | U12: ='MSPL-2(LOT)'!T141 -> 0 | V12: ='MSPL-2(LOT)'!U141 -> 207.3137
C13: 375 | D13: ='MSPL-2(LOT)'!E178 -> 888748 | E13: ='MSPL-2(LOT)'!G178 -> 6860589.5 | F13: ='MSPL-2(LOT)'!H178 -> 0 | G13: ='MSPL-2(LOT)'!I178 -> 6860589.5 | H13: ='MSPL-2(LOT)'!J178 -> 0 | I13: ='MSPL-2(LOT)'!K178 -> 888748 | J13: ='MSPL-2(LOT)'!L178 -> 0 | K13: ='MSPL-2(LOT)'!M178 -> 888748 | L13: ='MSPL-2(LOT)'!N178 -> 0 | ... N13: ='MSPL-2(LOT)'!P178 -> 0 | O13: =F13/E13% -> 0 | P13: =J13/D13% -> 0 | Q13: =L13/D13% -> 0 | S13: ='MSPL-2(LOT)'!R178 -> 13721.179 | T13: ='MSPL-2(LOT)'!S178 -> 211.09506 | U13: ='MSPL-2(LOT)'!T178 -> 0 | V13: ='MSPL-2(LOT)'!U178 -> 211.09506
C14: 401 | D14: ='MSPL-2(LOT)'!E215 -> 627854 | E14: ='MSPL-2(LOT)'!G215 -> 4908154 | F14: ='MSPL-2(LOT)'!H215 -> 0 | G14: ='MSPL-2(LOT)'!I215 -> 4908154 | H14: ='MSPL-2(LOT)'!J215 -> 0 | I14: ='MSPL-2(LOT)'!K215 -> 627854 | J14: ='MSPL-2(LOT)'!L215 -> 0 | K14: ='MSPL-2(LOT)'!M215 -> 627854 | L14: ='MSPL-2(LOT)'!N215 -> 0 | ... N14: ='MSPL-2(LOT)'!P215 -> 0 | O14: =F14/E14% -> 0 | P14: =J14/D14% -> 0 | Q14: =L14/D14% -> 0 | S14: ='MSPL-2(LOT)'!R215 -> 9816.308 | T14: ='MSPL-2(LOT)'!S215 -> 151.02012 | U14: ='MSPL-2(LOT)'!T215 -> 0 | V14: ='MSPL-2(LOT)'!U215 -> 151.02012
A15: 3 | B15: 7g | C15: 706 | D15: ='MSPL-2(LOT)'!E247 -> 385310 | E15: ='MSPL-2(LOT)'!G247 -> 1747602.8 | F15: ='MSPL-2(LOT)'!H247 -> 0 | G15: ='MSPL-2(LOT)'!I247 -> 1747602.8 | H15: ='MSPL-2(LOT)'!J247 -> 0 | I15: ='MSPL-2(LOT)'!K247 -> 385310 | J15: ='MSPL-2(LOT)'!L247 -> 0 | K15: ='MSPL-2(LOT)'!M247 -> 385310 | L15: ='MSPL-2(LOT)'!N247 -> 0 | ... N15: ='MSPL-2(LOT)'!P247 -> 0 | O15: =F15/E15% -> 0 | P15: =J15/D15% -> 0 | Q15: =L15/D15% -> 0 | S15: ='MSPL-2(LOT)'!R247 -> 6119.5505 | T15: ='MSPL-2(LOT)'!S247 -> 81.594007 | U15: ='MSPL-2(LOT)'!T247 -> 0 | V15: ='MSPL-2(LOT)'!U247 -> 81.594007
C16: 708 | D16: ='MSPL-2(LOT)'!E279 -> 490170 | E16: ='MSPL-2(LOT)'!G279 -> 2239361.2 | F16: ='MSPL-2(LOT)'!H279 -> 0 | G16: ='MSPL-2(LOT)'!I279 -> 2239361.2 | H16: ='MSPL-2(LOT)'!J279 -> 0 | I16: ='MSPL-2(LOT)'!K279 -> 490170 | J16: ='MSPL-2(LOT)'!L279 -> 0 | K16: ='MSPL-2(LOT)'!M279 -> 490170 | L16: ='MSPL-2(LOT)'!N279 -> 0 | ... N16: ='MSPL-2(LOT)'!P279 -> 0 | O16: =F16/E16% -> 0 | P16: =J16/D16% -> 0 | Q16: =L16/D16% -> 0 | S16: ='MSPL-2(LOT)'!R279 -> 7867.1375 | T16: ='MSPL-2(LOT)'!S279 -> 104.89517 | U16: ='MSPL-2(LOT)'!T279 -> 0 | V16: ='MSPL-2(LOT)'!U279 -> 104.89517
C17: 757 | D17: ='MSPL-2(LOT)'!E311 -> 419685 | E17: ='MSPL-2(LOT)'!G311 -> 1894800 | F17: ='MSPL-2(LOT)'!H311 -> 0 | G17: ='MSPL-2(LOT)'!I311 -> 1894800 | H17: ='MSPL-2(LOT)'!J311 -> 0 | I17: ='MSPL-2(LOT)'!K311 -> 419685 | J17: ='MSPL-2(LOT)'!L311 -> 0 | K17: ='MSPL-2(LOT)'!M311 -> 419685 | L17: ='MSPL-2(LOT)'!N311 -> 0 | ... N17: ='MSPL-2(LOT)'!P311 -> 0 | O17: =F17/E17% -> 0 | P17: =J17/D17% -> 0 | Q17: =L17/D17% -> 0 | S17: ='MSPL-2(LOT)'!R311 -> 6638.845 | T17: ='MSPL-2(LOT)'!S311 -> 88.517933 | U17: ='MSPL-2(LOT)'!T311 -> 0 | V17: ='MSPL-2(LOT)'!U311 -> 88.517933
C18: 759 | D18: ='MSPL-2(LOT)'!E343 -> 589637 | E18: ='MSPL-2(LOT)'!G343 -> 2669929.5 | F18: ='MSPL-2(LOT)'!H343 -> 0 | G18: ='MSPL-2(LOT)'!I343 -> 2669929.5 | H18: ='MSPL-2(LOT)'!J343 -> 0 | I18: ='MSPL-2(LOT)'!K343 -> 589637 | J18: ='MSPL-2(LOT)'!L343 -> 0 | K18: ='MSPL-2(LOT)'!M343 -> 589637 | L18: ='MSPL-2(LOT)'!N343 -> 0 | ... N18: ='MSPL-2(LOT)'!P343 -> 0 | O18: =F18/E18% -> 0 | P18: =J18/D18% -> 0 | Q18: =L18/D18% -> 0 | S18: ='MSPL-2(LOT)'!R343 -> 9367.9795 | T18: ='MSPL-2(LOT)'!S343 -> 124.90639 | U18: ='MSPL-2(LOT)'!T343 -> 0 | V18: ='MSPL-2(LOT)'!U343 -> 124.90639
C19: 862 | D19: ='MSPL-2(LOT)'!E375 -> 303805 | E19: ='MSPL-2(LOT)'!G375 -> 1376488.8 | F19: ='MSPL-2(LOT)'!H375 -> 0 | G19: ='MSPL-2(LOT)'!I375 -> 1376488.8 | H19: ='MSPL-2(LOT)'!J375 -> 0 | I19: ='MSPL-2(LOT)'!K375 -> 303805 | J19: ='MSPL-2(LOT)'!L375 -> 0 | K19: ='MSPL-2(LOT)'!M375 -> 303805 | L19: ='MSPL-2(LOT)'!N375 -> 0 | ... N19: ='MSPL-2(LOT)'!P375 -> 0 | O19: =F19/E19% -> 0 | P19: =J19/D19% -> 0 | Q19: =L19/D19% -> 0 | S19: ='MSPL-2(LOT)'!R375 -> 4840.735 | T19: ='MSPL-2(LOT)'!S375 -> 64.543133 | U19: ='MSPL-2(LOT)'!T375 -> 0 | V19: ='MSPL-2(LOT)'!U375 -> 64.543133
A20: 4 | B20: beg-mvwnZ¨ | C20: 926 | D20: ='MSPL-2(LOT)'!E401 -> 305465 | E20: ='MSPL-2(LOT)'!G401 -> 2445997.5 | F20: ='MSPL-2(LOT)'!H401 -> 0 | G20: ='MSPL-2(LOT)'!I401 -> 2445997.5 | H20: ='MSPL-2(LOT)'!J401 -> 0 | I20: ='MSPL-2(LOT)'!K401 -> 305465 | J20: ='MSPL-2(LOT)'!L401 -> 0 | K20: ='MSPL-2(LOT)'!M401 -> 305465 | L20: ='MSPL-2(LOT)'!N401 -> 0 | ... N20: ='MSPL-2(LOT)'!P401 -> 0 | O20: =F20/E20% -> 0 | P20: =J20/D20% -> 0 | Q20: =L20/D20% -> 0 | S20: ='MSPL-2(LOT)'!R401 -> 9340.845 | T20: ='MSPL-2(LOT)'!S401 -> 124.5446 | U20: ='MSPL-2(LOT)'!T401 -> 0 | V20: ='MSPL-2(LOT)'!U401 -> 124.5446
C21: 938 | D21: ='MSPL-2(LOT)'!E434 -> 346380 | E21: ='MSPL-2(LOT)'!G434 -> 2716987.5 | F21: ='MSPL-2(LOT)'!H434 -> 0 | G21: ='MSPL-2(LOT)'!I434 -> 2716987.5 | H21: ='MSPL-2(LOT)'!J434 -> 0 | I21: ='MSPL-2(LOT)'!K434 -> 346380 | J21: ='MSPL-2(LOT)'!L434 -> 0 | K21: ='MSPL-2(LOT)'!M434 -> 346380 | L21: ='MSPL-2(LOT)'!N434 -> 0 | ... N21: ='MSPL-2(LOT)'!P434 -> 0 | O21: =F21/E21% -> 0 | P21: =J21/D21% -> 0 | Q21: =L21/D21% -> 0 | S21: ='MSPL-2(LOT)'!R434 -> 10335.755 | T21: ='MSPL-2(LOT)'!S434 -> 137.81007 | U21: ='MSPL-2(LOT)'!T434 -> 0 | V21: ='MSPL-2(LOT)'!U434 -> 137.81007
C22: 953 | D22: ='MSPL-2(LOT)'!E467 -> 288238 | E22: ='MSPL-2(LOT)'!G467 -> 2210764 | F22: ='MSPL-2(LOT)'!H467 -> 0 | G22: ='MSPL-2(LOT)'!I467 -> 2210764 | H22: ='MSPL-2(LOT)'!J467 -> 0 | I22: ='MSPL-2(LOT)'!K467 -> 288238 | J22: ='MSPL-2(LOT)'!L467 -> 0 | K22: ='MSPL-2(LOT)'!M467 -> 288238 | L22: ='MSPL-2(LOT)'!N467 -> 0 | ... N22: ='MSPL-2(LOT)'!P467 -> 0 | O22: =F22/E22% -> 0 | P22: =J22/D22% -> 0 | Q22: =L22/D22% -> 0 | S22: ='MSPL-2(LOT)'!R467 -> 8474.296 | T22: ='MSPL-2(LOT)'!S467 -> 112.99061 | U22: ='MSPL-2(LOT)'!T467 -> 0 | V22: ='MSPL-2(LOT)'!U467 -> 112.99061
C23: 963 | D23: ='MSPL-2(LOT)'!E498 -> 306260 | E23: ='MSPL-2(LOT)'!G498 -> 2358035.8 | F23: ='MSPL-2(LOT)'!H498 -> 0 | G23: ='MSPL-2(LOT)'!I498 -> 2358035.8 | H23: ='MSPL-2(LOT)'!J498 -> 0 | I23: ='MSPL-2(LOT)'!K498 -> 306260 | J23: ='MSPL-2(LOT)'!L498 -> 0 | K23: ='MSPL-2(LOT)'!M498 -> 306260 | L23: ='MSPL-2(LOT)'!N498 -> 0 | ... N23: ='MSPL-2(LOT)'!P498 -> 0 | O23: =F23/E23% -> 0 | P23: =J23/D23% -> 0 | Q23: =L23/D23% -> 0 | S23: ='MSPL-2(LOT)'!R498 -> 8988.8635 | T23: ='MSPL-2(LOT)'!S498 -> 119.85151 | U23: ='MSPL-2(LOT)'!T498 -> 0 | V23: ='MSPL-2(LOT)'!U498 -> 119.85151
A24: 5 | B24: beg-Kvjvi | C24: 1122 | D24: ='MSPL-2(LOT)'!E524 -> 295274 | E24: ='MSPL-2(LOT)'!G524 -> 4708344.5 | F24: ='MSPL-2(LOT)'!H524 -> 0 | G24: ='MSPL-2(LOT)'!I524 -> 4708344.5 | H24: ='MSPL-2(LOT)'!J524 -> 0 | I24: ='MSPL-2(LOT)'!K524 -> 295274 | J24: ='MSPL-2(LOT)'!L524 -> 0 | K24: ='MSPL-2(LOT)'!M524 -> 295274 | L24: ='MSPL-2(LOT)'!N524 -> 0 | ... N24: ='MSPL-2(LOT)'!P524 -> 0 | O24: =F24/E24% -> 0 | P24: =J24/D24% -> 0 | Q24: =L24/D24% -> 0 | S24: ='MSPL-2(LOT)'!R524 -> 9416.689 | T24: ='MSPL-2(LOT)'!S524 -> 125.55585 | U24: ='MSPL-2(LOT)'!T524 -> 0 | V24: ='MSPL-2(LOT)'!U524 -> 125.55585
A25: 6 | B25: beg-`vwLj | C25: 1055 | D25: ='MSPL-2(LOT)'!E567 -> 287460 | E25: ='MSPL-2(LOT)'!G567 -> 2363805 | F25: ='MSPL-2(LOT)'!H567 -> 0 | G25: ='MSPL-2(LOT)'!I567 -> 2363805 | H25: ='MSPL-2(LOT)'!J567 -> 0 | I25: ='MSPL-2(LOT)'!K567 -> 287460 | J25: ='MSPL-2(LOT)'!L567 -> 0 | K25: ='MSPL-2(LOT)'!M567 -> 287460 | L25: ='MSPL-2(LOT)'!N567 -> 0 | ... N25: ='MSPL-2(LOT)'!P567 -> 0 | O25: =F25/E25% -> 0 | P25: =J25/D25% -> 0 | Q25: =L25/D25% -> 0 | S25: ='MSPL-2(LOT)'!R567 -> 8915.73 | T25: ='MSPL-2(LOT)'!S567 -> 118.8764 | U25: ='MSPL-2(LOT)'!T567 -> 0 | V25: ='MSPL-2(LOT)'!U567 -> 118.8764
A26: me©‡gvU | D26: =SUM(D8:D25) -> 8182376 | E26: =SUM(E8:E25) -> 59171909 | F26: =SUM(F8:F25) -> 0 | G26: =SUM(G8:G25) -> 59171909 | H26: =SUM(H8:H25) -> 0 | I26: =SUM(I8:I25) -> 8182376 | J26: =SUM(J8:J25) -> 0 | K26: =SUM(K8:K25) -> 8182376 | ... N26: =SUM(N8:N25) -> 0 | O26: =F26/E26% -> 0 | P26: =J26/D26% -> 0 | Q26: =L26/D26% -> 0 | R26: =SUM(R8:R25) -> 0 | S26: =SUM(S8:S25) -> 155186.01 | T26: =SUM(T8:T25) -> 2208.8219 | U26: =SUM(U8:U25) -> 0 | V26: =SUM(V8:V25) -> 2208.8219
A28: BDwbU-3 (Qbcvov, AvovBnvRvi, bvivqbMÄ)
A29: µ: | B29: ‡kÖbx | C29: jU msL¨v | D29: ‡gvU eB | E29: wcÖw›Us (B‡¤úªkb) | H29: wcÖw›Us (eB) | J29: evBwÛs | L29: ‡Wwjfvix | N29: ÷K eB | O29: Kv‡Ri nvi-% | R29: ‡Wwjfvix †kl ZvwiL | S29: ‡ccvi
E30: ‡gvU B‡¤úªkb | F30: wcÖw›Us | G30: evwK | H30: wcÖw›Us (eB) | I30: evwK | J30: evBwÛs | K30: evwK | L30: ‡Wwjfvix | M30: evwK | O30: wcÖw›Us | P30: evBwÛs | Q30: ‡Wwjfvix | S30: wig | T30: Ub | U30: e¨envi | V30: evwK
A31: 1 | B31: cÖvBgvix | C31: 376 | D31: ='MSPL-3(Lot)'!F34 -> 801962 | E31: ='MSPL-3(Lot)'!H34 -> 6178376.2 | F31: ='MSPL-3(Lot)'!I34 -> 0 | G31: ='MSPL-3(Lot)'!J34 -> 6178376.2 | H31: ='MSPL-3(Lot)'!K34 -> 0 | I31: ='MSPL-3(Lot)'!L34 -> 801962 | J31: ='MSPL-3(Lot)'!M34 -> 0 | K31: ='MSPL-3(Lot)'!N34 -> 801962 | L31: ='MSPL-3(Lot)'!O34 -> 0 | ... N31: ='MSPL-3(Lot)'!Q34 -> 0 | O31: =F31/E31% -> 0 | P31: =J31/D31% -> 0 | Q31: =L31/D31% -> 0 | S31: ='MSPL-3(Lot)'!S34 -> 12356.752 | T31: ='MSPL-3(Lot)'!T34 -> 190.10388 | U31: ='MSPL-3(Lot)'!U34 -> 0 | V31: ='MSPL-3(Lot)'!V34 -> 190.10388
C32: 379 | D32: ='MSPL-3(Lot)'!F70 -> 594871 | E32: ='MSPL-3(Lot)'!H70 -> 4575704.8 | F32: ='MSPL-3(Lot)'!I70 -> 0 | G32: ='MSPL-3(Lot)'!J70 -> 4575704.8 | H32: ='MSPL-3(Lot)'!K70 -> 0 | I32: ='MSPL-3(Lot)'!L70 -> 594871 | J32: ='MSPL-3(Lot)'!M70 -> 0 | K32: ='MSPL-3(Lot)'!N70 -> 594871 | L32: ='MSPL-3(Lot)'!O70 -> 0 | ... N32: ='MSPL-3(Lot)'!Q70 -> 0 | O32: =F32/E32% -> 0 | P32: =J32/D32% -> 0 | Q32: =L32/D32% -> 0 | S32: ='MSPL-3(Lot)'!S70 -> 9151.4095 | T32: ='MSPL-3(Lot)'!T70 -> 140.79092 | U32: ='MSPL-3(Lot)'!U70 -> 0 | V32: ='MSPL-3(Lot)'!V70 -> 140.79092
A33: 2 | B33: Be‡Z`vqx | C33: 2022 | D33: ='MSPL-3(Lot)'!F99 -> 862368 | E33: ='MSPL-3(Lot)'!H99 -> 4873221.8 | F33: ='MSPL-3(Lot)'!I99 -> 0 | G33: ='MSPL-3(Lot)'!J99 -> 4873221.8 | H33: ='MSPL-3(Lot)'!K99 -> 0 | I33: ='MSPL-3(Lot)'!L99 -> 862368 | J33: ='MSPL-3(Lot)'!M99 -> 0 | K33: ='MSPL-3(Lot)'!N99 -> 862368 | L33: ='MSPL-3(Lot)'!O99 -> 0 | ... N33: ='MSPL-3(Lot)'!Q99 -> 0 | O33: =F33/E33% -> 0 | P33: =J33/D33% -> 0 | Q33: =L33/D33% -> 0 | S33: ='MSPL-3(Lot)'!S99 -> 9746.4435 | T33: ='MSPL-3(Lot)'!T99 -> 149.94528 | U33: ='MSPL-3(Lot)'!U99 -> 0 | V33: ='MSPL-3(Lot)'!V99 -> 149.94528
A34: 3 | B34: 6ô gva¨wgK | C34: 646 | D34: ='MSPL-3(Lot)'!F136 -> 407322 | E34: ='MSPL-3(Lot)'!H136 -> 1567424.8 | F34: ='MSPL-3(Lot)'!I136 -> 0 | G34: ='MSPL-3(Lot)'!J136 -> 1567424.8 | H34: ='MSPL-3(Lot)'!K136 -> 0 | I34: ='MSPL-3(Lot)'!L136 -> 407322 | J34: ='MSPL-3(Lot)'!M136 -> 0 | K34: ='MSPL-3(Lot)'!N136 -> 407322 | L34: ='MSPL-3(Lot)'!O136 -> 0 | ... N34: ='MSPL-3(Lot)'!Q136 -> 0 | O34: =F34/E34% -> 0 | P34: =J34/D34% -> 0 | Q34: =L34/D34% -> 0 | S34: ='MSPL-3(Lot)'!S136 -> 5418.2295 | T34: ='MSPL-3(Lot)'!T136 -> 72.24306 | U34: ='MSPL-3(Lot)'!U136 -> 0 | V34: ='MSPL-3(Lot)'!V136 -> 72.24306
A35: 4 | B35: 6ô `vwLj | C35: 667 | D35: ='MSPL-3(Lot)'!F166 -> 693254 | E35: ='MSPL-3(Lot)'!H166 -> 2768978.5 | F35: ='MSPL-3(Lot)'!I166 -> 0 | G35: ='MSPL-3(Lot)'!J166 -> 2768978.5 | H35: ='MSPL-3(Lot)'!K166 -> 0 | I35: ='MSPL-3(Lot)'!L166 -> 693254 | J35: ='MSPL-3(Lot)'!M166 -> 0 | K35: ='MSPL-3(Lot)'!N166 -> 693254 | L35: ='MSPL-3(Lot)'!O166 -> 0 | ... N35: ='MSPL-3(Lot)'!Q166 -> 0 | O35: =F35/E35% -> 0 | P35: =J35/D35% -> 0 | Q35: =L35/D35% -> 0 | S35: ='MSPL-3(Lot)'!S166 -> 10012.573 | T35: ='MSPL-3(Lot)'!T166 -> 133.50097 | U35: ='MSPL-3(Lot)'!U166 -> 0 | V35: ='MSPL-3(Lot)'!V166 -> 133.50097
A36: 5 | B36: 8g gva¨wgK | C36: 834 | D36: ='MSPL-3(Lot)'!F209 -> 472937 | E36: ='MSPL-3(Lot)'!H209 -> 2312999 | F36: ='MSPL-3(Lot)'!I209 -> 0 | G36: ='MSPL-3(Lot)'!J209 -> 2312999 | H36: ='MSPL-3(Lot)'!K209 -> 0 | I36: ='MSPL-3(Lot)'!L209 -> 472937 | J36: ='MSPL-3(Lot)'!M209 -> 0 | K36: ='MSPL-3(Lot)'!N209 -> 472937 | L36: ='MSPL-3(Lot)'!O209 -> 0 | ... N36: ='MSPL-3(Lot)'!Q209 -> 0 | O36: =F36/E36% -> 0 | P36: =J36/D36% -> 0 | Q36: =L36/D36% -> 0 | S36: ='MSPL-3(Lot)'!S209 -> 8532.764 | T36: ='MSPL-3(Lot)'!T209 -> 113.77019 | U36: ='MSPL-3(Lot)'!U209 -> 0 | V36: ='MSPL-3(Lot)'!V209 -> 113.77019
C37: 843 | D37: ='MSPL-3(Lot)'!F246 -> 464240 | E37: ='MSPL-3(Lot)'!H246 -> 2283330 | F37: ='MSPL-3(Lot)'!I246 -> 0 | G37: ='MSPL-3(Lot)'!J246 -> 2283330 | H37: ='MSPL-3(Lot)'!K246 -> 0 | I37: ='MSPL-3(Lot)'!L246 -> 464240 | J37: ='MSPL-3(Lot)'!M246 -> 0 | K37: ='MSPL-3(Lot)'!N246 -> 464240 | L37: ='MSPL-3(Lot)'!O246 -> 0 | ... N37: ='MSPL-3(Lot)'!Q246 -> 0 | O37: =F37/E37% -> 0 | P37: =J37/D37% -> 0 | Q37: =L37/D37% -> 0 | S37: ='MSPL-3(Lot)'!S246 -> 8432.59 | T37: ='MSPL-3(Lot)'!T246 -> 112.43453 | U37: ='MSPL-3(Lot)'!U246 -> 0 | V37: ='MSPL-3(Lot)'!V246 -> 112.43453
C38: 854 | D38: ='MSPL-3(Lot)'!F284 -> 428175 | E38: ='MSPL-3(Lot)'!H284 -> 2104866 | F38: ='MSPL-3(Lot)'!I284 -> 0 | G38: ='MSPL-3(Lot)'!J284 -> 2104866 | H38: ='MSPL-3(Lot)'!K284 -> 0 | I38: ='MSPL-3(Lot)'!L284 -> 428175 | J38: ='MSPL-3(Lot)'!M284 -> 0 | K38: ='MSPL-3(Lot)'!N284 -> 428175 | L38: ='MSPL-3(Lot)'!O284 -> 0 | ... N38: ='MSPL-3(Lot)'!Q284 -> 0 | O38: =F38/E38% -> 0 | P38: =J38/D38% -> 0 | Q38: =L38/D38% -> 0 | S38: ='MSPL-3(Lot)'!S284 -> 7765.508 | T38: ='MSPL-3(Lot)'!T284 -> 103.54011 | U38: ='MSPL-3(Lot)'!U284 -> 0 | V38: ='MSPL-3(Lot)'!V284 -> 103.54011
C39: 865 | D39: ='MSPL-3(Lot)'!F321 -> 605335 | E39: ='MSPL-3(Lot)'!H321 -> 2976051.5 | F39: ='MSPL-3(Lot)'!I321 -> 0 | G39: ='MSPL-3(Lot)'!J321 -> 2976051.5 | H39: ='MSPL-3(Lot)'!K321 -> 0 | I39: ='MSPL-3(Lot)'!L321 -> 605335 | J39: ='MSPL-3(Lot)'!M321 -> 0 | K39: ='MSPL-3(Lot)'!N321 -> 605335 | L39: ='MSPL-3(Lot)'!O321 -> 0 | ... N39: ='MSPL-3(Lot)'!Q321 -> 0 | O39: =F39/E39% -> 0 | P39: =J39/D39% -> 0 | Q39: =L39/D39% -> 0 | S39: ='MSPL-3(Lot)'!S321 -> 10986.893 | T39: ='MSPL-3(Lot)'!T321 -> 146.49191 | U39: ='MSPL-3(Lot)'!U321 -> 0 | V39: ='MSPL-3(Lot)'!V321 -> 146.49191
C40: 872 | D40: ='MSPL-3(Lot)'!F357 -> 521500 | E40: ='MSPL-3(Lot)'!H357 -> 2556333.2 | F40: ='MSPL-3(Lot)'!I357 -> 0 | G40: ='MSPL-3(Lot)'!J357 -> 2556333.2 | H40: ='MSPL-3(Lot)'!K357 -> 0 | I40: ='MSPL-3(Lot)'!L357 -> 521500 | J40: ='MSPL-3(Lot)'!M357 -> 0 | K40: ='MSPL-3(Lot)'!N357 -> 521500 | L40: ='MSPL-3(Lot)'!O357 -> 0 | ... N40: ='MSPL-3(Lot)'!Q357 -> 0 | O40: =F40/E40% -> 0 | P40: =J40/D40% -> 0 | Q40: =L40/D40% -> 0 | S40: ='MSPL-3(Lot)'!S357 -> 9429.9565 | T40: ='MSPL-3(Lot)'!T357 -> 125.73275 | U40: ='MSPL-3(Lot)'!U357 -> 0 | V40: ='MSPL-3(Lot)'!V357 -> 125.73275
C41: 877 | D41: ='MSPL-3(Lot)'!F394 -> 441582 | E41: ='MSPL-3(Lot)'!H394 -> 2172001.2 | F41: ='MSPL-3(Lot)'!I394 -> 0 | G41: ='MSPL-3(Lot)'!J394 -> 2172001.2 | H41: ='MSPL-3(Lot)'!K394 -> 0 | I41: ='MSPL-3(Lot)'!L394 -> 441582 | J41: ='MSPL-3(Lot)'!M394 -> 0 | K41: ='MSPL-3(Lot)'!N394 -> 441582 | L41: ='MSPL-3(Lot)'!O394 -> 0 | ... N41: ='MSPL-3(Lot)'!Q394 -> 0 | O41: =F41/E41% -> 0 | P41: =J41/D41% -> 0 | Q41: =L41/D41% -> 0 | S41: ='MSPL-3(Lot)'!S394 -> 8022.6045 | T41: ='MSPL-3(Lot)'!T394 -> 106.96806 | U41: ='MSPL-3(Lot)'!U394 -> 0 | V41: ='MSPL-3(Lot)'!V394 -> 106.96806
A42: me©‡gvU | D42: =SUM(D31:D41) -> 6293546 | E42: =SUM(E31:E41) -> 34369287 | F42: =SUM(F31:F41) -> 0 | G42: =SUM(G31:G41) -> 34369287 | H42: =SUM(H31:H41) -> 0 | I42: =SUM(I31:I41) -> 6293546 | J42: =SUM(J31:J41) -> 0 | K42: =SUM(K31:K41) -> 6293546 | ... N42: =SUM(N31:N41) -> 0 | O42: =F42/E42% -> 0 | P42: =J42/D42% -> 0 | Q42: =L42/D42% -> 0 | R42: =SUM(R31:R41) -> 0 | S42: =SUM(S31:S41) -> 99855.724 | T42: =SUM(T31:T41) -> 1395.5217 | U42: =SUM(U31:U41) -> 0 | V42: =SUM(V31:V41) -> 1395.5217
...

Sheet MSPL-2 (Class)
A1: gvóvi wm‡g· †ccvi wjt (BDwbU-2)
A2: Kz`ve,c~evBj, MvRxcyi|
A3: RvZxq wkÿvµg I cvV¨cy¯ÍK †evW© Gi 2027 wkÿve‡l©i cvV¨cy¯ÍK g~`ªY, evuavB I mieiv‡ni wbwg‡Ë cwiKíbv cÖwZ‡e`b
A4: (cÖvK-cÖv_wgK-2027) | AD4: ZvwiLt-02/08/26
A5: SL | B5: Book Name | C5: Class | D5: Forma | F5: Lot | K5: Total Books | L5: Forma | M5: Plate | P5: Cover | R5: Printing Impassion | U5: Printing Book | W5: Binding | Y5: Delivery | AA5: Stock Book | AB5: Gluing Rem | AC5: Wating for Binding | AD5: Paper | AH5: Binder
F6: Lot-123 | M6: Total | N6: Rec: | O6: Due | P6: Received | Q6: Due | R6: Total | S6: Print | T6: Due | U6: Print | V6: Due | W6: Binding | X6: Due | Y6: Delivery | Z6: Due | AD6: Rem | AE6: MT | AF6: Used | AG6: Due
A7: 1 | B7: Amar Boi | C7: Pre-Primary | D7: 21.5 | F7: 66398 | K7: =F7 -> 66398 | L7: 2 | M7: 192 | O7: =M7-N7 -> 192 | Q7: =K7-P7 -> 66398 | R7: =D7/L7*K7 -> 713778.5 | S7: ='MSPL-2(LOT)'!H7 -> 0 | T7: =R7-S7 -> 713778.5 | U7: =S7/D7*2 -> 0 | V7: =K7-U7 -> 66398 | W7: ='MSPL-2(LOT)'!L7 -> 0 | X7: =F7-W7 -> 66398 | Y7: ='MSPL-2(LOT)'!N7 -> 0 | Z7: =K7-Y7 -> 66398 | AA7: =W7-Y7 -> 0 | AB7: =D7*W7/1000 -> 0 | AC7: =U7-W7 -> 0 | AD7: =D7*K7/1000 -> 1427.557 | AE7: =AD7/50 -> 28.55114 | AF7: =D7*U7/1000/50 -> 0 | AG7: =AE7-AF7 -> 28.55114
A8: 2 | B8: Khata | D8: 17 | F8: 66398 | K8: =F8 -> 66398 | L8: 2 | M8: 18 | O8: =M8-N8 -> 18 | Q8: =K8-P8 -> 66398 | R8: =D8/L8*K8 -> 564383 | S8: ='MSPL-2(LOT)'!H8 -> 0 | T8: =R8-S8 -> 564383 | U8: =S8/D8*2 -> 0 | V8: =K8-U8 -> 66398 | W8: ='MSPL-2(LOT)'!L8 -> 0 | X8: =F8-W8 -> 66398 | Y8: ='MSPL-2(LOT)'!N8 -> 0 | Z8: =K8-Y8 -> 66398 | AA8: =W8-Y8 -> 0 | AB8: =D8*W8/1000 -> 0 | AC8: =U8-W8 -> 0 | AD8: =D8*K8/1000 -> 1128.766 | AE8: =AD8/65 -> 17.365631 | AF8: =D8*U8/1000/65 -> 0 | AG8: =AE8-AF8 -> 17.365631
A9: Grand Total | F9: =SUM(F7:F8) -> 132796 | G9: =SUM(G7:G8) -> 0 | H9: =SUM(H7:H8) -> 0 | I9: =SUM(I7:I8) -> 0 | J9: =SUM(J7:J8) -> 0 | K9: =SUM(K7:K8) -> 132796 | L9: =SUM(L7:L8) -> 4 | M9: =SUM(M7:M8) -> 210 | ... AB9: =SUM(AB7:AB8) -> 0 | AD9: =SUM(AD7:AD8) -> 2556.323 | AE9: =SUM(AE7:AE8) -> 45.916771 | AF9: =SUM(AF7:AF8) -> 0 | AG9: =SUM(AG7:AG8) -> 45.916771 | AH9: =SUM(AH7:AH8) -> 0
AB12: Manager (Production)
A37: gvóvi wm‡g· †ccvi wjt (BDwbU-2)
A38: Kz`ve,c~evBj, MvRxcyi|
A39: RvZxq wkÿvµg I cvV¨cy¯ÍK †evW© Gi 2027 wkÿve‡l©i cvV¨cy¯ÍK g~`ªY, evuavB I mieiv‡ni wbwg‡Ë cwiKíbv cÖwZ‡e`b
A40: cÖvBgvix-(1-5)-2027 | AD40: =AD4 -> ZvwiLt-02/08/26
A41: SL | B41: Book Name | C41: Class | D41: Forma | F41: Lot | K41: Total Books | L41: Forma | M41: Plate | P41: Cover | R41: Printing Impassion | U41: Printing Book | W41: Binding | Y41: Delivery | AA41: Stock Book | AB41: Gluing Rem | AC41: Wating for Binding | AD41: Paper | AH41: Binder
F42: Lot-329 | G42: Lot-338 | H42: Lot-347 | I42: Lot-375 | J42: Lot-401 | M42: Total | N42: Rec: | O42: Due | P42: Received | Q42: Due | R42: Total | S42: Print | T42: Due | U42: Print | V42: Due | W42: Binding | X42: Due | Y42: Delivery | Z42: Due | AD42: Rem | AE42: MT | AF42: Used | AG42: Due
A43: 1 | B43: Bangla | C43: One | D43: 11 | F43: 37420 | G43: 34712 | H43: 39266 | I43: 39879 | J43: 22797 | K43: =SUM(F43:J43) -> 174074 | L43: 2 | M43: 144 | O43: =M43-N43 -> 144 | Q43: =K43-P43 -> 174074 | R43: =D43/L43*K43 -> 957407 | S43: ='MSPL-2(LOT)'!H40+'MSPL-2(LOT)'!H77+'MSPL-2(LOT)'!H114+'MSPL-2(LOT)'!H151+'MSPL-2(LOT)'!H188 -> 0 | T43: =R43-S43 -> 957407 | U43: =S43/D43*2 -> 0 | V43: =K43-U43 -> 174074 | W43: ='MSPL-2(LOT)'!L40+'MSPL-2(LOT)'!L77+'MSPL-2(LOT)'!L114+'MSPL-2(LOT)'!L151+'MSPL-2(LOT)'!L188 -> 0 | X43: =K43-W43 -> 174074 | Y43: ='MSPL-2(LOT)'!N40+'MSPL-2(LOT)'!N77+'MSPL-2(LOT)'!N114+'MSPL-2(LOT)'!N151+'MSPL-2(LOT)'!N188 -> 0 | Z43: =K43-Y43 -> 174074 | AA43: =W43-Y43 -> 0 | AB43: =D43*W43/1000 -> 0 | AC43: =U43-W43 -> 0 | AD43: =D43*K43/1000 -> 1914.814 | AE43: =AD43/65 -> 29.458677 | AF43: =D43*U43/1000/65 -> 0 | AG43: =AE43-AF43 -> 29.458677
A44: 2 | B44: English | D44: 12 | F44: 37420 | G44: 34712 | H44: 39266 | I44: 39879 | J44: 22797 | K44: =SUM(F44:J44) -> 174074 | L44: 2 | M44: 144 | O44: =M44-N44 -> 144 | Q44: =K44-P44 -> 174074 | R44: =D44/L44*K44 -> 1044444 | S44: ='MSPL-2(LOT)'!H41+'MSPL-2(LOT)'!H78+'MSPL-2(LOT)'!H115+'MSPL-2(LOT)'!H152+'MSPL-2(LOT)'!H189 -> 0 | T44: =R44-S44 -> 1044444 | U44: =S44/D44*2 -> 0 | V44: =K44-U44 -> 174074 | W44: ='MSPL-2(LOT)'!L41+'MSPL-2(LOT)'!L78+'MSPL-2(LOT)'!L115+'MSPL-2(LOT)'!L152+'MSPL-2(LOT)'!L189 -> 0 | X44: =K44-W44 -> 174074 | Y44: ='MSPL-2(LOT)'!N41+'MSPL-2(LOT)'!N78+'MSPL-2(LOT)'!N115+'MSPL-2(LOT)'!N152+'MSPL-2(LOT)'!N189 -> 0 | Z44: =K44-Y44 -> 174074 | AA44: =W44-Y44 -> 0 | AB44: =D44*W44/1000 -> 0 | AC44: =U44-W44 -> 0 | AD44: =D44*K44/1000 -> 2088.888 | AE44: =AD44/65 -> 32.136738 | AF44: =D44*U44/1000/65 -> 0 | AG44: =AE44-AF44 -> 32.136738
A45: 3 | B45: Mathematics | D45: 15 | F45: 37420 | G45: 34712 | H45: 39266 | I45: 39879 | J45: 22797 | K45: =SUM(F45:J45) -> 174074 | L45: 2 | M45: 192 | O45: =M45-N45 -> 192 | Q45: =K45-P45 -> 174074 | R45: =D45/L45*K45 -> 1305555 | S45: ='MSPL-2(LOT)'!H42+'MSPL-2(LOT)'!H79+'MSPL-2(LOT)'!H116+'MSPL-2(LOT)'!H153+'MSPL-2(LOT)'!H190 -> 0 | T45: =R45-S45 -> 1305555 | U45: =S45/D45*2 -> 0 | V45: =K45-U45 -> 174074 | W45: ='MSPL-2(LOT)'!L42+'MSPL-2(LOT)'!L79+'MSPL-2(LOT)'!L116+'MSPL-2(LOT)'!L153+'MSPL-2(LOT)'!L190 -> 0 | X45: =K45-W45 -> 174074 | Y45: ='MSPL-2(LOT)'!N42+'MSPL-2(LOT)'!N79+'MSPL-2(LOT)'!N116+'MSPL-2(LOT)'!N153+'MSPL-2(LOT)'!N190 -> 0 | Z45: =K45-Y45 -> 174074 | AA45: =W45-Y45 -> 0 | AB45: =D45*W45/1000 -> 0 | AC45: =U45-W45 -> 0 | AD45: =D45*K45/1000 -> 2611.11 | AE45: =AD45/65 -> 40.170923 | AF45: =D45*U45/1000/65 -> 0 | AG45: =AE45-AF45 -> 40.170923
A46: 4 | B46: Bangla | C46: Two | D46: 9 | F46: 37362 | G46: 34222 | H46: 37948 | I46: 37815 | J46: 23865 | K46: =SUM(F46:J46) -> 171212 | L46: 2 | M46: 120 | O46: =M46-N46 -> 120 | Q46: =K46-P46 -> 171212 | R46: =D46/L46*K46 -> 770454 | S46: ='MSPL-2(LOT)'!H43+'MSPL-2(LOT)'!H80+'MSPL-2(LOT)'!H117+'MSPL-2(LOT)'!H154+'MSPL-2(LOT)'!H191 -> 0 | T46: =R46-S46 -> 770454 | U46: =S46/D46*2 -> 0 | V46: =K46-U46 -> 171212 | W46: ='MSPL-2(LOT)'!L43+'MSPL-2(LOT)'!L80+'MSPL-2(LOT)'!L117+'MSPL-2(LOT)'!L154+'MSPL-2(LOT)'!L191 -> 0 | X46: =K46-W46 -> 171212 | Y46: ='MSPL-2(LOT)'!N43+'MSPL-2(LOT)'!N80+'MSPL-2(LOT)'!N117+'MSPL-2(LOT)'!N154+'MSPL-2(LOT)'!N191 -> 0 | Z46: =K46-Y46 -> 171212 | AA46: =W46-Y46 -> 0 | AB46: =D46*W46/1000 -> 0 | AC46: =U46-W46 -> 0 | AD46: =D46*K46/1000 -> 1540.908 | AE46: =AD46/65 -> 23.706277 | AF46: =D46*U46/1000/65 -> 0 | AG46: =AE46-AF46 -> 23.706277
A47: 5 | B47: English | D47: 13 | F47: 37362 | G47: 34222 | H47: 37948 | I47: 37815 | J47: 23865 | K47: =SUM(F47:J47) -> 171212 | L47: 2 | M47: 168 | O47: =M47-N47 -> 168 | Q47: =K47-P47 -> 171212 | R47: =D47/L47*K47 -> 1112878 | S47: ='MSPL-2(LOT)'!H44+'MSPL-2(LOT)'!H81+'MSPL-2(LOT)'!H118+'MSPL-2(LOT)'!H155+'MSPL-2(LOT)'!H192 -> 0 | T47: =R47-S47 -> 1112878 | U47: =S47/D47*2 -> 0 | V47: =K47-U47 -> 171212 | W47: ='MSPL-2(LOT)'!L44+'MSPL-2(LOT)'!L81+'MSPL-2(LOT)'!L118+'MSPL-2(LOT)'!L155+'MSPL-2(LOT)'!L192 -> 0 | X47: =K47-W47 -> 171212 | Y47: ='MSPL-2(LOT)'!N44+'MSPL-2(LOT)'!N81+'MSPL-2(LOT)'!N118+'MSPL-2(LOT)'!N155+'MSPL-2(LOT)'!N192 -> 0 | Z47: =K47-Y47 -> 171212 | AA47: =W47-Y47 -> 0 | AB47: =D47*W47/1000 -> 0 | AC47: =U47-W47 -> 0 | AD47: =D47*K47/1000 -> 2225.756 | AE47: =AD47/65 -> 34.2424 | AF47: =D47*U47/1000/65 -> 0 | AG47: =AE47-AF47 -> 34.2424
A48: 6 | B48: Mathematics | D48: 17 | F48: 37362 | G48: 34222 | H48: 37948 | I48: 37815 | J48: 23865 | K48: =SUM(F48:J48) -> 171212 | L48: 2 | M48: 216 | O48: =M48-N48 -> 216 | Q48: =K48-P48 -> 171212 | R48: =D48/L48*K48 -> 1455302 | S48: ='MSPL-2(LOT)'!H45+'MSPL-2(LOT)'!H82+'MSPL-2(LOT)'!H119+'MSPL-2(LOT)'!H156+'MSPL-2(LOT)'!H193 -> 0 | T48: =R48-S48 -> 1455302 | U48: =S48/D48*2 -> 0 | V48: =K48-U48 -> 171212 | W48: ='MSPL-2(LOT)'!L45+'MSPL-2(LOT)'!L82+'MSPL-2(LOT)'!L119+'MSPL-2(LOT)'!L156+'MSPL-2(LOT)'!L193 -> 0 | X48: =K48-W48 -> 171212 | Y48: ='MSPL-2(LOT)'!N45+'MSPL-2(LOT)'!N82+'MSPL-2(LOT)'!N119+'MSPL-2(LOT)'!N156+'MSPL-2(LOT)'!N193 -> 0 | Z48: =K48-Y48 -> 171212 | AA48: =W48-Y48 -> 0 | AB48: =D48*W48/1000 -> 0 | AC48: =U48-W48 -> 0 | AD48: =D48*K48/1000 -> 2910.604 | AE48: =AD48/65 -> 44.778523 | AF48: =D48*U48/1000/65 -> 0 | AG48: =AE48-AF48 -> 44.778523
A49: 7 | B49: Bangla | C49: Three | D49: 13.5 | F49: 36610 | G49: 34662 | H49: 38282 | I49: 37390 | J49: 25868 | K49: =SUM(F49:J49) -> 172812 | L49: 2 | M49: 168 | O49: =M49-N49 -> 168 | Q49: =K49-P49 -> 172812 | R49: =D49/L49*K49 -> 1166481 | S49: ='MSPL-2(LOT)'!H46+'MSPL-2(LOT)'!H83+'MSPL-2(LOT)'!H120+'MSPL-2(LOT)'!H157+'MSPL-2(LOT)'!H194 -> 0 | T49: =R49-S49 -> 1166481 | U49: =S49/D49*2 -> 0 | V49: =K49-U49 -> 172812 | W49: ='MSPL-2(LOT)'!L46+'MSPL-2(LOT)'!L83+'MSPL-2(LOT)'!L120+'MSPL-2(LOT)'!L157+'MSPL-2(LOT)'!L194 -> 0 | X49: =K49-W49 -> 172812 | Y49: ='MSPL-2(LOT)'!N46+'MSPL-2(LOT)'!N83+'MSPL-2(LOT)'!N120+'MSPL-2(LOT)'!N157+'MSPL-2(LOT)'!N194 -> 0 | Z49: =K49-Y49 -> 172812 | AA49: =W49-Y49 -> 0 | AB49: =D49*W49/1000 -> 0 | AC49: =U49-W49 -> 0 | AD49: =D49*K49/1000 -> 2332.962 | AE49: =AD49/65 -> 35.891723 | AF49: =D49*U49/1000/65 -> 0 | AG49: =AE49-AF49 -> 35.891723
A50: 8 | B50: English | D50: 16 | F50: 36610 | G50: 34662 | H50: 38282 | I50: 37390 | J50: 25868 | K50: =SUM(F50:J50) -> 172812 | L50: 2 | M50: 192 | O50: =M50-N50 -> 192 | Q50: =K50-P50 -> 172812 | R50: =D50/L50*K50 -> 1382496 | S50: ='MSPL-2(LOT)'!H47+'MSPL-2(LOT)'!H84+'MSPL-2(LOT)'!H121+'MSPL-2(LOT)'!H158+'MSPL-2(LOT)'!H195 -> 0 | T50: =R50-S50 -> 1382496 | U50: =S50/D50*2 -> 0 | V50: =K50-U50 -> 172812 | W50: ='MSPL-2(LOT)'!L47+'MSPL-2(LOT)'!L84+'MSPL-2(LOT)'!L121+'MSPL-2(LOT)'!L158+'MSPL-2(LOT)'!L195 -> 0 | X50: =K50-W50 -> 172812 | Y50: ='MSPL-2(LOT)'!N47+'MSPL-2(LOT)'!N84+'MSPL-2(LOT)'!N121+'MSPL-2(LOT)'!N158+'MSPL-2(LOT)'!N195 -> 0 | Z50: =K50-Y50 -> 172812 | AA50: =W50-Y50 -> 0 | AB50: =D50*W50/1000 -> 0 | AC50: =U50-W50 -> 0 | AD50: =D50*K50/1000 -> 2764.992 | AE50: =AD50/65 -> 42.538338 | AF50: =D50*U50/1000/65 -> 0 | AG50: =AE50-AF50 -> 42.538338
A51: 9 | B51: Mathematics | D51: 20 | F51: 36610 | G51: 34662 | H51: 38282 | I51: 37390 | J51: 25868 | K51: =SUM(F51:J51) -> 172812 | L51: 2 | M51: 240 | O51: =M51-N51 -> 240 | Q51: =K51-P51 -> 172812 | R51: =D51/L51*K51 -> 1728120 | S51: ='MSPL-2(LOT)'!H48+'MSPL-2(LOT)'!H85+'MSPL-2(LOT)'!H122+'MSPL-2(LOT)'!H159+'MSPL-2(LOT)'!H196 -> 0 | T51: =R51-S51 -> 1728120 | U51: =S51/D51*2 -> 0 | V51: =K51-U51 -> 172812 | W51: ='MSPL-2(LOT)'!L48+'MSPL-2(LOT)'!L85+'MSPL-2(LOT)'!L122+'MSPL-2(LOT)'!L159+'MSPL-2(LOT)'!L196 -> 0 | X51: =K51-W51 -> 172812 | Y51: ='MSPL-2(LOT)'!N48+'MSPL-2(LOT)'!N85+'MSPL-2(LOT)'!N122+'MSPL-2(LOT)'!N159+'MSPL-2(LOT)'!N196 -> 0 | Z51: =K51-Y51 -> 172812 | AA51: =W51-Y51 -> 0 | AB51: =D51*W51/1000 -> 0 | AC51: =U51-W51 -> 0 | AD51: =D51*K51/1000 -> 3456.24 | AE51: =AD51/65 -> 53.172923 | AF51: =D51*U51/1000/65 -> 0 | AG51: =AE51-AF51 -> 53.172923
A52: 10 | B52: B&G | D52: 14.5 | F52: 36610 | G52: 34662 | H52: 38282 | I52: 37390 | J52: 25868 | K52: =SUM(F52:J52) -> 172812 | L52: 2 | M52: 168 | O52: =M52-N52 -> 168 | Q52: =K52-P52 -> 172812 | R52: =D52/L52*K52 -> 1252887 | S52: ='MSPL-2(LOT)'!H49+'MSPL-2(LOT)'!H86+'MSPL-2(LOT)'!H123+'MSPL-2(LOT)'!H160+'MSPL-2(LOT)'!H197 -> 0 | T52: =R52-S52 -> 1252887 | U52: =S52/D52*2 -> 0 | V52: =K52-U52 -> 172812 | W52: ='MSPL-2(LOT)'!L49+'MSPL-2(LOT)'!L86+'MSPL-2(LOT)'!L123+'MSPL-2(LOT)'!L160+'MSPL-2(LOT)'!L197 -> 0 | X52: =K52-W52 -> 172812 | Y52: ='MSPL-2(LOT)'!N49+'MSPL-2(LOT)'!N86+'MSPL-2(LOT)'!N123+'MSPL-2(LOT)'!N160+'MSPL-2(LOT)'!N197 -> 0 | Z52: =K52-Y52 -> 172812 | AA52: =W52-Y52 -> 0 | AB52: =D52*W52/1000 -> 0 | AC52: =U52-W52 -> 0 | AD52: =D52*K52/1000 -> 2505.774 | AE52: =AD52/65 -> 38.550369 | AF52: =D52*U52/1000/65 -> 0 | AG52: =AE52-AF52 -> 38.550369
A53: 11 | B53: Science | D53: 19 | F53: 36610 | G53: 34662 | H53: 38282 | I53: 37390 | J53: 25868 | K53: =SUM(F53:J53) -> 172812 | L53: 2 | M53: 240 | O53: =M53-N53 -> 240 | Q53: =K53-P53 -> 172812 | R53: =D53/L53*K53 -> 1641714 | S53: ='MSPL-2(LOT)'!H50+'MSPL-2(LOT)'!H87+'MSPL-2(LOT)'!H124+'MSPL-2(LOT)'!H161+'MSPL-2(LOT)'!H198 -> 0 | T53: =R53-S53 -> 1641714 | U53: =S53/D53*2 -> 0 | V53: =K53-U53 -> 172812 | W53: ='MSPL-2(LOT)'!L50+'MSPL-2(LOT)'!L87+'MSPL-2(LOT)'!L124+'MSPL-2(LOT)'!L161+'MSPL-2(LOT)'!L198 -> 0 | X53: =K53-W53 -> 172812 | Y53: ='MSPL-2(LOT)'!N50+'MSPL-2(LOT)'!N87+'MSPL-2(LOT)'!N124+'MSPL-2(LOT)'!N161+'MSPL-2(LOT)'!N198 -> 0 | Z53: =K53-Y53 -> 172812 | AA53: =W53-Y53 -> 0 | AB53: =D53*W53/1000 -> 0 | AC53: =U53-W53 -> 0 | AD53: =D53*K53/1000 -> 3283.428 | AE53: =AD53/65 -> 50.514277 | AF53: =D53*U53/1000/65 -> 0 | AG53: =AE53-AF53 -> 50.514277
A54: 12 | B54: Islam | D54: 9 | F54: 33535 | G54: 30510 | H54: 34143 | I54: 36004 | J54: 22405 | K54: =SUM(F54:J54) -> 156597 | L54: 2 | M54: 120 | O54: =M54-N54 -> 120 | Q54: =K54-P54 -> 156597 | R54: =D54/L54*K54 -> 704686.5 | S54: ='MSPL-2(LOT)'!H51+'MSPL-2(LOT)'!H88+'MSPL-2(LOT)'!H125+'MSPL-2(LOT)'!H162+'MSPL-2(LOT)'!H199 -> 0 | T54: =R54-S54 -> 704686.5 | U54: =S54/D54*2 -> 0 | V54: =K54-U54 -> 156597 | W54: ='MSPL-2(LOT)'!L51+'MSPL-2(LOT)'!L88+'MSPL-2(LOT)'!L125+'MSPL-2(LOT)'!L162+'MSPL-2(LOT)'!L199 -> 0 | X54: =K54-W54 -> 156597 | Y54: ='MSPL-2(LOT)'!N51+'MSPL-2(LOT)'!N88+'MSPL-2(LOT)'!N125+'MSPL-2(LOT)'!N162+'MSPL-2(LOT)'!N199 -> 0 | Z54: =K54-Y54 -> 156597 | AA54: =W54-Y54 -> 0 | AB54: =D54*W54/1000 -> 0 | AC54: =U54-W54 -> 0 | AD54: =D54*K54/1000 -> 1409.373 | AE54: =AD54/65 -> 21.682662 | AF54: =D54*U54/1000/65 -> 0 | AG54: =AE54-AF54 -> 21.682662
A55: 13 | B55: Hindu | D55: 11.5 | F55: 3067 | G55: 4011 | H55: 4089 | I55: 1132 | J55: 3332 | K55: =SUM(F55:J55) -> 15631 | L55: 2 | M55: 56 | O55: =M55-N55 -> 56 | Q55: =K55-P55 -> 15631 | R55: =D55/L55*K55 -> 89878.25 | S55: ='MSPL-2(LOT)'!H52+'MSPL-2(LOT)'!H89+'MSPL-2(LOT)'!H126+'MSPL-2(LOT)'!H163+'MSPL-2(LOT)'!H200 -> 0 | T55: =R55-S55 -> 89878.25 | U55: =S55/D55*2 -> 0 | V55: =K55-U55 -> 15631 | W55: ='MSPL-2(LOT)'!L52+'MSPL-2(LOT)'!L89+'MSPL-2(LOT)'!L126+'MSPL-2(LOT)'!L163+'MSPL-2(LOT)'!L200 -> 0 | X55: =K55-W55 -> 15631 | Y55: ='MSPL-2(LOT)'!N52+'MSPL-2(LOT)'!N89+'MSPL-2(LOT)'!N126+'MSPL-2(LOT)'!N163+'MSPL-2(LOT)'!N200 -> 0 | Z55: =K55-Y55 -> 15631 | AA55: =W55-Y55 -> 0 | AB55: =D55*W55/1000 -> 0 | AC55: =U55-W55 -> 0 | AD55: =D55*K55/1000 -> 179.7565 | AE55: =AD55/65 -> 2.7654846 | AF55: =D55*U55/1000/65 -> 0 | AG55: =AE55-AF55 -> 2.7654846
A56: 14 | B56: Bangla | C56: Four | D56: 16.5 | F56: 34384 | G56: 33805 | H56: 36268 | I56: 36127 | J56: 28087 | K56: =SUM(F56:J56) -> 168671 | L56: 2 | M56: 216 | O56: =M56-N56 -> 216 | Q56: =K56-P56 -> 168671 | R56: =D56/L56*K56 -> 1391535.8 | S56: ='MSPL-2(LOT)'!H53+'MSPL-2(LOT)'!H90+'MSPL-2(LOT)'!H127+'MSPL-2(LOT)'!H164+'MSPL-2(LOT)'!H201 -> 0 | T56: =R56-S56 -> 1391535.8 | U56: =S56/D56*2 -> 0 | V56: =K56-U56 -> 168671 | W56: ='MSPL-2(LOT)'!L53+'MSPL-2(LOT)'!L90+'MSPL-2(LOT)'!L127+'MSPL-2(LOT)'!L164+'MSPL-2(LOT)'!L201 -> 0 | X56: =K56-W56 -> 168671 | Y56: ='MSPL-2(LOT)'!N53+'MSPL-2(LOT)'!N90+'MSPL-2(LOT)'!N127+'MSPL-2(LOT)'!N164+'MSPL-2(LOT)'!N201 -> 0 | Z56: =K56-Y56 -> 168671 | AA56: =W56-Y56 -> 0 | AB56: =D56*W56/1000 -> 0 | AC56: =U56-W56 -> 0 | AD56: =D56*K56/1000 -> 2783.0715 | AE56: =AD56/65 -> 42.816485 | AF56: =D56*U56/1000/65 -> 0 | AG56: =AE56-AF56 -> 42.816485
A57: 15 | B57: English | D57: 12 | F57: 34384 | G57: 33805 | H57: 36268 | I57: 36127 | J57: 28087 | K57: =SUM(F57:J57) -> 168671 | L57: 2 | M57: 144 | O57: =M57-N57 -> 144 | Q57: =K57-P57 -> 168671 | R57: =D57/L57*K57 -> 1012026 | S57: ='MSPL-2(LOT)'!H54+'MSPL-2(LOT)'!H91+'MSPL-2(LOT)'!H128+'MSPL-2(LOT)'!H165+'MSPL-2(LOT)'!H202 -> 0 | T57: =R57-S57 -> 1012026 | U57: =S57/D57*2 -> 0 | V57: =K57-U57 -> 168671 | W57: ='MSPL-2(LOT)'!L54+'MSPL-2(LOT)'!L91+'MSPL-2(LOT)'!L128+'MSPL-2(LOT)'!L165+'MSPL-2(LOT)'!L202 -> 0 | X57: =K57-W57 -> 168671 | Y57: ='MSPL-2(LOT)'!N54+'MSPL-2(LOT)'!N91+'MSPL-2(LOT)'!N128+'MSPL-2(LOT)'!N165+'MSPL-2(LOT)'!N202 -> 0 | Z57: =K57-Y57 -> 168671 | AA57: =W57-Y57 -> 0 | AB57: =D57*W57/1000 -> 0 | AC57: =U57-W57 -> 0 | AD57: =D57*K57/1000 -> 2024.052 | AE57: =AD57/65 -> 31.139262 | AF57: =D57*U57/1000/65 -> 0 | AG57: =AE57-AF57 -> 31.139262
A58: 16 | B58: Mathematics | D58: 22.5 | F58: 34384 | G58: 33805 | H58: 36268 | I58: 36127 | J58: 28087 | K58: =SUM(F58:J58) -> 168671 | L58: 2 | M58: 288 | O58: =M58-N58 -> 288 | Q58: =K58-P58 -> 168671 | R58: =D58/L58*K58 -> 1897548.8 | S58: ='MSPL-2(LOT)'!H55+'MSPL-2(LOT)'!H92+'MSPL-2(LOT)'!H129+'MSPL-2(LOT)'!H166+'MSPL-2(LOT)'!H203 -> 0 | T58: =R58-S58 -> 1897548.8 | U58: =S58/D58*2 -> 0 | V58: =K58-U58 -> 168671 | W58: ='MSPL-2(LOT)'!L55+'MSPL-2(LOT)'!L92+'MSPL-2(LOT)'!L129+'MSPL-2(LOT)'!L166+'MSPL-2(LOT)'!L203 -> 0 | X58: =K58-W58 -> 168671 | Y58: ='MSPL-2(LOT)'!N55+'MSPL-2(LOT)'!N92+'MSPL-2(LOT)'!N129+'MSPL-2(LOT)'!N166+'MSPL-2(LOT)'!N203 -> 0 | Z58: =K58-Y58 -> 168671 | AA58: =W58-Y58 -> 0 | AB58: =D58*W58/1000 -> 0 | AC58: =U58-W58 -> 0 | AD58: =D58*K58/1000 -> 3795.0975 | AE58: =AD58/65 -> 58.386115 | AF58: =D58*U58/1000/65 -> 0 | AG58: =AE58-AF58 -> 58.386115
